<?xml version="1.0" encoding="utf-8"?><testsuites><testsuite name="silius" errors="2" failures="20" skipped="0" tests="167" time="186.346" timestamp="2023-10-09T16:18:29.457639" hostname="fv-az257-30"><testcase classname="tests.bundle.test_bundle" name="test_bundle_replace_op[only_priority_fee_bump]" time="0.239" /><testcase classname="tests.bundle.test_bundle" name="test_bundle_replace_op[only_max_fee_bump]" time="0.205" /><testcase classname="tests.bundle.test_bundle" name="test_bundle_replace_op[with_same_fee]" time="0.317" /><testcase classname="tests.bundle.test_bundle" name="test_bundle_replace_op[with_less_fee]" time="0.205" /><testcase classname="tests.bundle.test_bundle" name="test_bundle_replace_op[fee_bump_below_threshold]" time="0.210" /><testcase classname="tests.bundle.test_bundle" name="test_bundle_replace_op[fee_bump_at_threshold]" time="0.369" /><testcase classname="tests.bundle.test_bundle" name="test_bundle_replace_op[fee_bump_above_threshold]" time="0.360" /><testcase classname="tests.bundle.test_bundle" name="test_mempool_reputation_rules_all_entities[SREP-020-banned-entity-not-allowed-banned-sender]" time="0.440"><failure message="AttributeError: 'Error' object has no attribute 'result'">tests/bundle/test_bundle.py:148: in test_mempool_reputation_rules_all_entities
    set_reputation(
tests/utils.py:200: in set_reputation
    )
E   AttributeError: 'Error' object has no attribute 'result'</failure><system-out>--------------------------------- Captured Log ---------------------------------

--------------------------------- Captured Out ---------------------------------

</system-out><system-err>--------------------------------- Captured Err ---------------------------------

</system-err></testcase><testcase classname="tests.bundle.test_bundle" name="test_mempool_reputation_rules_all_entities[SREP-020-banned-entity-not-allowed-banned-paymaster]" time="0.262"><failure message="AttributeError: 'Error' object has no attribute 'result'">tests/bundle/test_bundle.py:154: in test_mempool_reputation_rules_all_entities
    set_reputation(
tests/utils.py:200: in set_reputation
    )
E   AttributeError: 'Error' object has no attribute 'result'</failure><system-out>--------------------------------- Captured Log ---------------------------------

--------------------------------- Captured Out ---------------------------------

</system-out><system-err>--------------------------------- Captured Err ---------------------------------

</system-err></testcase><testcase classname="tests.bundle.test_bundle" name="test_mempool_reputation_rules_all_entities[SREP-020-banned-entity-not-allowed-banned-factory]" time="0.269"><failure message="AttributeError: 'Error' object has no attribute 'result'">tests/bundle/test_bundle.py:160: in test_mempool_reputation_rules_all_entities
    set_reputation(
tests/utils.py:200: in set_reputation
    )
E   AttributeError: 'Error' object has no attribute 'result'</failure><system-out>--------------------------------- Captured Log ---------------------------------

--------------------------------- Captured Out ---------------------------------

</system-out><system-err>--------------------------------- Captured Err ---------------------------------

</system-err></testcase><testcase classname="tests.bundle.test_bundle" name="test_mempool_reputation_rules_all_entities[SREP-030-throttled-entity-allowed-a-little-throttled-sender]" time="0.239"><failure message="AttributeError: 'Error' object has no attribute 'result'">tests/bundle/test_bundle.py:148: in test_mempool_reputation_rules_all_entities
    set_reputation(
tests/utils.py:200: in set_reputation
    )
E   AttributeError: 'Error' object has no attribute 'result'</failure><system-out>--------------------------------- Captured Log ---------------------------------

--------------------------------- Captured Out ---------------------------------

</system-out><system-err>--------------------------------- Captured Err ---------------------------------

</system-err></testcase><testcase classname="tests.bundle.test_bundle" name="test_mempool_reputation_rules_all_entities[SREP-030-throttled-entity-allowed-a-little-throttled-paymaster]" time="0.346"><failure message="AttributeError: 'Error' object has no attribute 'result'">tests/bundle/test_bundle.py:154: in test_mempool_reputation_rules_all_entities
    set_reputation(
tests/utils.py:200: in set_reputation
    )
E   AttributeError: 'Error' object has no attribute 'result'</failure><system-out>--------------------------------- Captured Log ---------------------------------

--------------------------------- Captured Out ---------------------------------

</system-out><system-err>--------------------------------- Captured Err ---------------------------------

</system-err></testcase><testcase classname="tests.bundle.test_bundle" name="test_mempool_reputation_rules_all_entities[SREP-030-throttled-entity-allowed-a-little-throttled-factory]" time="0.234"><failure message="AttributeError: 'Error' object has no attribute 'result'">tests/bundle/test_bundle.py:160: in test_mempool_reputation_rules_all_entities
    set_reputation(
tests/utils.py:200: in set_reputation
    )
E   AttributeError: 'Error' object has no attribute 'result'</failure><system-out>--------------------------------- Captured Log ---------------------------------

--------------------------------- Captured Out ---------------------------------

</system-out><system-err>--------------------------------- Captured Err ---------------------------------

</system-err></testcase><testcase classname="tests.bundle.test_bundle" name="test_mempool_reputation_rules_all_entities[UREP-010 UREP-020-unstaked-entity-allowed-function-unstaked-sender]" time="0.275"><failure message="AttributeError: 'Error' object has no attribute 'result'">tests/bundle/test_bundle.py:148: in test_mempool_reputation_rules_all_entities
    set_reputation(
tests/utils.py:200: in set_reputation
    )
E   AttributeError: 'Error' object has no attribute 'result'</failure><system-out>--------------------------------- Captured Log ---------------------------------

--------------------------------- Captured Out ---------------------------------

</system-out><system-err>--------------------------------- Captured Err ---------------------------------

</system-err></testcase><testcase classname="tests.bundle.test_bundle" name="test_mempool_reputation_rules_all_entities[UREP-010 UREP-020-unstaked-entity-allowed-function-unstaked-paymaster]" time="0.272"><failure message="AttributeError: 'Error' object has no attribute 'result'">tests/bundle/test_bundle.py:154: in test_mempool_reputation_rules_all_entities
    set_reputation(
tests/utils.py:200: in set_reputation
    )
E   AttributeError: 'Error' object has no attribute 'result'</failure><system-out>--------------------------------- Captured Log ---------------------------------

--------------------------------- Captured Out ---------------------------------

</system-out><system-err>--------------------------------- Captured Err ---------------------------------

</system-err></testcase><testcase classname="tests.bundle.test_bundle" name="test_mempool_reputation_rules_all_entities[UREP-010 UREP-020-unstaked-entity-allowed-function-unstaked-factory]" time="0.239"><failure message="AttributeError: 'Error' object has no attribute 'result'">tests/bundle/test_bundle.py:160: in test_mempool_reputation_rules_all_entities
    set_reputation(
tests/utils.py:200: in set_reputation
    )
E   AttributeError: 'Error' object has no attribute 'result'</failure><system-out>--------------------------------- Captured Log ---------------------------------

--------------------------------- Captured Out ---------------------------------

</system-out><system-err>--------------------------------- Captured Err ---------------------------------

</system-err></testcase><testcase classname="tests.bundle.test_bundle" name="test_max_allowed_ops_unstaked_sender" time="0.976" /><testcase classname="tests.bundle.test_bundle" name="test_max_allowed_ops_staked_sender" time="1.330" /><testcase classname="tests.bundle.test_bundle" name="test_ban_user_op_access_other_ops_sender_in_bundle" time="1.102" /><testcase classname="tests.bundle.test_bundle" name="test_ban_user_sender_double_role_in_bundle" time="0.516"><failure message="Exception: expected error object, got:&#10;Ok(result='0x2ef4fd3f8969a4d44f03512ef7747d04c798de683f9369d2613ca83f9e062822', id=113)">tests/utils.py:115: in assert_rpc_error
    assert response.code == code
E   AttributeError: 'Ok' object has no attribute 'code'

The above exception was the direct cause of the following exception:
tests/bundle/test_bundle.py:359: in test_ban_user_sender_double_role_in_bundle
    assert_rpc_error(
tests/utils.py:118: in assert_rpc_error
    raise Exception(f"expected error object, got:\n{response}") from exc
E   Exception: expected error object, got:
E   Ok(result='0x2ef4fd3f8969a4d44f03512ef7747d04c798de683f9369d2613ca83f9e062822', id=113)</failure><system-out>--------------------------------- Captured Log ---------------------------------

--------------------------------- Captured Out ---------------------------------

</system-out><system-err>--------------------------------- Captured Err ---------------------------------

</system-err></testcase><testcase classname="tests.bundle.test_bundle" name="test_stake_check_in_bundler" time="0.065"><failure message="AttributeError: 'Error' object has no attribute 'result'">tests/bundle/test_bundle.py:382: in test_stake_check_in_bundler
    response = get_stake_status(paymaster_contract.address, entrypoint_contract.address)
tests/utils.py:165: in get_stake_status
    .result
E   AttributeError: 'Error' object has no attribute 'result'</failure><system-out>--------------------------------- Captured Log ---------------------------------

--------------------------------- Captured Out ---------------------------------

</system-out><system-err>--------------------------------- Captured Err ---------------------------------

</system-err></testcase><testcase classname="tests.bundle.test_codehash" name="test_codehash_changed" time="1.366" /><testcase classname="tests.bundle.test_storage_rules" name="test_rule[[STO-000]unstaked][paymaster][no_storage][ok]" time="0.383" /><testcase classname="tests.bundle.test_storage_rules" name="test_rule[[STO-031]unstaked][paymaster][storage][drop]" time="0.386" /><testcase classname="tests.bundle.test_storage_rules" name="test_rule[[STO-032]unstaked][paymaster][reference_storage][drop]" time="0.404" /><testcase classname="tests.bundle.test_storage_rules" name="test_rule[[STO-032]unstaked][paymaster][reference_storage_struct][drop]" time="0.429" /><testcase classname="tests.bundle.test_storage_rules" name="test_rule[[STO-010]unstaked][paymaster][account_storage][ok]" time="0.426" /><testcase classname="tests.bundle.test_storage_rules" name="test_rule[[STO-021]unstaked][paymaster][account_reference_storage][ok]" time="0.409" /><testcase classname="tests.bundle.test_storage_rules" name="test_rule[[STO-021]unstaked][paymaster][account_reference_storage_struct][ok]" time="0.438" /><testcase classname="tests.bundle.test_storage_rules" name="test_rule[[STO-022]unstaked][paymaster][account_reference_storage_init_code][drop0]" time="0.730" /><testcase classname="tests.bundle.test_storage_rules" name="test_rule[[EREP-050]unstaked][paymaster][context][drop]" time="0.306" /><testcase classname="tests.bundle.test_storage_rules" name="test_rule[[STO-032]unstaked][paymaster][external_storage][drop]" time="0.482" /><testcase classname="tests.bundle.test_storage_rules" name="test_rule[[OP-020]unstaked][paymaster][out_of_gas][drop]" time="0.613" /><testcase classname="tests.bundle.test_storage_rules" name="test_rule[[OP-020]unstaked][paymaster][sstore_out_of_gas][drop]" time="0.426" /><testcase classname="tests.bundle.test_storage_rules" name="test_rule[[STO-000]staked][paymaster][no_storage][ok]" time="0.418" /><testcase classname="tests.bundle.test_storage_rules" name="test_rule[[STO-031]staked][paymaster][storage][ok]" time="0.420" /><testcase classname="tests.bundle.test_storage_rules" name="test_rule[[STO-032]staked][paymaster][reference_storage][ok]" time="0.436" /><testcase classname="tests.bundle.test_storage_rules" name="test_rule[[STO-032]staked][paymaster][reference_storage_struct][ok]" time="0.490" /><testcase classname="tests.bundle.test_storage_rules" name="test_rule[[STO-010]staked][paymaster][account_storage][ok]" time="0.461" /><testcase classname="tests.bundle.test_storage_rules" name="test_rule[[STO-021]staked][paymaster][account_reference_storage][ok]" time="0.476" /><testcase classname="tests.bundle.test_storage_rules" name="test_rule[[STO-021]staked][paymaster][account_reference_storage_struct][ok]" time="0.477" /><testcase classname="tests.bundle.test_storage_rules" name="test_rule[[STO-022]staked][paymaster][account_reference_storage_init_code][ok]" time="0.770" /><testcase classname="tests.bundle.test_storage_rules" name="test_rule[[EREP-050]staked][paymaster][context][ok]" time="0.349" /><testcase classname="tests.bundle.test_storage_rules" name="test_rule[[STO-031]staked][paymaster][external_storage][drop]" time="0.446" /><testcase classname="tests.bundle.test_storage_rules" name="test_rule[[OP-020]staked][paymaster][out_of_gas][drop]" time="0.554" /><testcase classname="tests.bundle.test_storage_rules" name="test_rule[[OP-020]staked][paymaster][sstore_out_of_gas][drop]" time="0.456" /><testcase classname="tests.bundle.test_storage_rules" name="test_rule[[STO-000]unstaked][factory][no_storage][ok]" time="0.564" /><testcase classname="tests.bundle.test_storage_rules" name="test_rule[[STO-000]unstaked][factory][storage][drop]" time="0.576" /><testcase classname="tests.bundle.test_storage_rules" name="test_rule[[STO-000]unstaked][factory][reference_storage][drop]" time="0.604" /><testcase classname="tests.bundle.test_storage_rules" name="test_rule[[STO-032]unstaked][factory][reference_storage_struct][drop]" time="0.621" /><testcase classname="tests.bundle.test_storage_rules" name="test_rule[[STO-010]unstaked][factory][account_storage][ok]" time="0.601" /><testcase classname="tests.bundle.test_storage_rules" name="test_rule[[STO-021]unstaked][factory][account_reference_storage][drop]" time="0.693" /><testcase classname="tests.bundle.test_storage_rules" name="test_rule[[STO-021]unstaked][factory][account_reference_storage_struct][drop]" time="0.631" /><testcase classname="tests.bundle.test_storage_rules" name="test_rule[[STO-000]unstaked][factory][external_storage][drop]" time="0.599" /><testcase classname="tests.bundle.test_storage_rules" name="test_rule[[OP-042]unstaked][factory][EXTCODEx_CALLx_undeployed_sender][ok]" time="0.545" /><testcase classname="tests.bundle.test_storage_rules" name="test_rule[[OP-041]unstaked][factory][EXTCODESIZE_undeployed_contract][drop]" time="0.565" /><testcase classname="tests.bundle.test_storage_rules" name="test_rule[[OP-041]unstaked][factory][EXTCODEHASH_undeployed_contract][drop]" time="0.554" /><testcase classname="tests.bundle.test_storage_rules" name="test_rule[[OP-041]unstaked][factory][EXTCODECOPY_undeployed_contract][drop]" time="0.553" /><testcase classname="tests.bundle.test_storage_rules" name="test_rule[[OP-041]unstaked][factory][CALL_undeployed_contract][drop]" time="0.649" /><testcase classname="tests.bundle.test_storage_rules" name="test_rule[[OP-041]unstaked][factory][CALLCODE_undeployed_contract][drop]" time="0.543" /><testcase classname="tests.bundle.test_storage_rules" name="test_rule[[OP-041]unstaked][factory][DELEGATECALL_undeployed_contract][drop]" time="0.553" /><testcase classname="tests.bundle.test_storage_rules" name="test_rule[[OP-041]unstaked][factory][STATICCALL_undeployed_contract][drop]" time="0.563" /><testcase classname="tests.bundle.test_storage_rules" name="test_rule[[OP-020]unstaked][factory][out_of_gas][drop]" time="0.720" /><testcase classname="tests.bundle.test_storage_rules" name="test_rule[[OP-020]unstaked][factory][sstore_out_of_gas][drop]" time="0.611" /><testcase classname="tests.bundle.test_storage_rules" name="test_rule[[STO-000]staked][factory][no_storage][ok]" time="0.609" /><testcase classname="tests.bundle.test_storage_rules" name="test_rule[[STO-031]staked][factory][storage][ok]" time="0.621" /><testcase classname="tests.bundle.test_storage_rules" name="test_rule[[STO-032]staked][factory][reference_storage][ok]" time="0.670" /><testcase classname="tests.bundle.test_storage_rules" name="test_rule[[STO-032]staked][factory][reference_storage_struct][ok]" time="0.675" /><testcase classname="tests.bundle.test_storage_rules" name="test_rule[[STO-010]staked][factory][account_storage][ok]" time="0.645" /><testcase classname="tests.bundle.test_storage_rules" name="test_rule[[STO-021]staked][factory][account_reference_storage][ok]" time="0.641" /><testcase classname="tests.bundle.test_storage_rules" name="test_rule[[STO-021]staked][factory][account_reference_storage_struct][ok]" time="0.663" /><testcase classname="tests.bundle.test_storage_rules" name="test_rule[[STO-000]staked][factory][external_storage][drop]" time="0.654" /><testcase classname="tests.bundle.test_storage_rules" name="test_rule[[OP-020]staked][factory][out_of_gas][drop]" time="0.743" /><testcase classname="tests.bundle.test_storage_rules" name="test_rule[[OP-020]staked][factory][sstore_out_of_gas][drop]" time="0.629" /><testcase classname="tests.bundle.test_storage_rules" name="test_rule[[STO-000]unstaked][account][no_storage][ok]" time="0.395" /><testcase classname="tests.bundle.test_storage_rules" name="test_rule[[STO-010]unstaked][account][account_storage][ok]" time="0.407" /><testcase classname="tests.bundle.test_storage_rules" name="test_rule[[STO-021]unstaked][account][account_reference_storage][ok]" time="0.364" /><testcase classname="tests.bundle.test_storage_rules" name="test_rule[[STO-022]unstaked][account][account_reference_storage_init_code][drop]" time="0.569" /><testcase classname="tests.bundle.test_storage_rules" name="test_rule[[STO-022]unstaked][account][account_reference_storage_init_code][ok]" time="0.643" /><testcase classname="tests.bundle.test_storage_rules" name="test_rule[[STO-022]unstaked][paymaster][account_reference_storage_init_code][drop1]" time="0.754" /><testcase classname="tests.bundle.test_storage_rules" name="test_rule[[STO-021]unstaked][account][account_reference_storage_struct][ok]" time="0.384" /><testcase classname="tests.bundle.test_storage_rules" name="test_rule[[STO-000]unstaked][account][external_storage][drop]" time="0.379" /><testcase classname="tests.bundle.test_storage_rules" name="test_rule[[OP-020]unstaked][account][out_of_gas][drop]" time="0.474" /><testcase classname="tests.bundle.test_storage_rules" name="test_rule[[OP-020]unstaked][account][sstore_out_of_gas][drop]" time="0.403" /><testcase classname="tests.bundle.test_storage_rules" name="test_rule[[STO-000]staked][account][no_storage][ok]" time="0.392" /><testcase classname="tests.bundle.test_storage_rules" name="test_rule[[STO-010]staked][account][account_storage][ok]" time="0.390" /><testcase classname="tests.bundle.test_storage_rules" name="test_rule[[STO-021]staked][account][account_reference_storage][ok]" time="0.428" /><testcase classname="tests.bundle.test_storage_rules" name="test_rule[[STO-021]staked][account][account_reference_storage_struct][ok]" time="0.418" /><testcase classname="tests.bundle.test_storage_rules" name="test_rule[[OP-020]staked][account][out_of_gas][drop]" time="0.505" /><testcase classname="tests.bundle.test_storage_rules" name="test_rule[[OP-020]staked][account][sstore_out_of_gas][drop]" time="0.415" /><testcase classname="tests.bundle.test_storage_rules" name="test_rule[[STO-000]staked][account][external_storage][drop]" time="0.419" /><testcase classname="tests.bundle.test_storage_rules" name="test_rule[[OP-011]unstaked][account][entryPoint_call_balanceOf][drop]" time="0.387" /><testcase classname="tests.bundle.test_storage_rules" name="test_rule[[OP-061]unstaked][account][eth_value_transfer_forbidden][drop]" time="0.348" /><testcase classname="tests.bundle.test_storage_rules" name="test_rule[[OP-053]unstaked][account][eth_value_transfer_entryPoint][ok]" time="0.494" /><testcase classname="tests.bundle.test_storage_rules" name="test_rule[[OP-052]unstaked][account][eth_value_transfer_entryPoint_depositTo][ok]" time="0.440" /><testcase classname="tests.bundle.test_storage_rules" name="test_rule[[OP-041]unstaked][account][EXTCODESIZE_undeployed_contract][drop]" time="0.302" /><testcase classname="tests.bundle.test_storage_rules" name="test_rule[[OP-041]unstaked][account][EXTCODEHASH_undeployed_contract][drop]" time="0.335" /><testcase classname="tests.bundle.test_storage_rules" name="test_rule[[OP-041]unstaked][account][EXTCODECOPY_undeployed_contract][drop]" time="0.304" /><testcase classname="tests.bundle.test_storage_rules" name="test_rule[[OP-054]unstaked][account][EXTCODESIZE_entrypoint][drop]" time="0.328" /><testcase classname="tests.bundle.test_storage_rules" name="test_rule[[OP-054]unstaked][account][EXTCODEHASH_entrypoint][drop]" time="0.354" /><testcase classname="tests.bundle.test_storage_rules" name="test_rule[[OP-054]unstaked][account][EXTCODECOPY_entrypoint][drop]" time="0.328" /><testcase classname="tests.bundle.test_storage_rules" name="test_rule[[OP-041]unstaked][account][CALL_undeployed_contract][drop]" time="0.317" /><testcase classname="tests.bundle.test_storage_rules" name="test_rule[[OP-041]unstaked][account][CALLCODE_undeployed_contract][drop]" time="0.302" /><testcase classname="tests.bundle.test_storage_rules" name="test_rule[[OP-041]unstaked][account][DELEGATECALL_undeployed_contract][drop]" time="0.306" /><testcase classname="tests.bundle.test_storage_rules" name="test_rule[[OP-041]unstaked][account][STATICCALL_undeployed_contract][drop]" time="0.320" /><testcase classname="tests.bundle.test_storage_rules" name="test_rule[[OP-062]unstaked][account][CALL_undeployed_contract_allowed_precompile][ok]" time="0.362" /><testcase classname="tests.opbanning.test_op_banning" name="test_account_banned_opcode[GAS]" time="0.238" /><testcase classname="tests.opbanning.test_op_banning" name="test_account_banned_opcode[NUMBER]" time="0.237" /><testcase classname="tests.opbanning.test_op_banning" name="test_account_banned_opcode[TIMESTAMP]" time="0.238" /><testcase classname="tests.opbanning.test_op_banning" name="test_account_banned_opcode[COINBASE]" time="0.233" /><testcase classname="tests.opbanning.test_op_banning" name="test_account_banned_opcode[DIFFICULTY]" time="0.240" /><testcase classname="tests.opbanning.test_op_banning" name="test_account_banned_opcode[BASEFEE]" time="0.239" /><testcase classname="tests.opbanning.test_op_banning" name="test_account_banned_opcode[GASLIMIT]" time="0.243" /><testcase classname="tests.opbanning.test_op_banning" name="test_account_banned_opcode[GASPRICE]" time="0.249" /><testcase classname="tests.opbanning.test_op_banning" name="test_account_banned_opcode[SELFBALANCE]" time="0.249" /><testcase classname="tests.opbanning.test_op_banning" name="test_account_banned_opcode[BALANCE]" time="0.252" /><testcase classname="tests.opbanning.test_op_banning" name="test_account_banned_opcode[ORIGIN]" time="0.252" /><testcase classname="tests.opbanning.test_op_banning" name="test_account_banned_opcode[BLOCKHASH]" time="0.268" /><testcase classname="tests.opbanning.test_op_banning" name="test_account_banned_opcode[CREATE]" time="0.276" /><testcase classname="tests.opbanning.test_op_banning" name="test_account_banned_opcode[CREATE2]" time="0.268" /><testcase classname="tests.opbanning.test_op_banning" name="test_account_banned_opcode[SELFDESTRUCT]" time="0.276" /><testcase classname="tests.opbanning.test_op_banning" name="test_account_allowed_opcode_sequence[GAS CALL]" time="0.299" /><testcase classname="tests.opbanning.test_op_banning" name="test_account_allowed_opcode_sequence[GAS DELEGATECALL]" time="0.314" /><testcase classname="tests.opbanning.test_op_banning" name="test_paymaster_banned_opcode[GAS]" time="0.317" /><testcase classname="tests.opbanning.test_op_banning" name="test_paymaster_banned_opcode[NUMBER]" time="0.325" /><testcase classname="tests.opbanning.test_op_banning" name="test_paymaster_banned_opcode[TIMESTAMP]" time="0.327" /><testcase classname="tests.opbanning.test_op_banning" name="test_paymaster_banned_opcode[COINBASE]" time="0.421" /><testcase classname="tests.opbanning.test_op_banning" name="test_paymaster_banned_opcode[DIFFICULTY]" time="0.361" /><testcase classname="tests.opbanning.test_op_banning" name="test_paymaster_banned_opcode[BASEFEE]" time="0.322" /><testcase classname="tests.opbanning.test_op_banning" name="test_paymaster_banned_opcode[GASLIMIT]" time="0.320" /><testcase classname="tests.opbanning.test_op_banning" name="test_paymaster_banned_opcode[GASPRICE]" time="0.330" /><testcase classname="tests.opbanning.test_op_banning" name="test_paymaster_banned_opcode[SELFBALANCE]" time="0.341" /><testcase classname="tests.opbanning.test_op_banning" name="test_paymaster_banned_opcode[BALANCE]" time="0.332" /><testcase classname="tests.opbanning.test_op_banning" name="test_paymaster_banned_opcode[ORIGIN]" time="0.336" /><testcase classname="tests.opbanning.test_op_banning" name="test_paymaster_banned_opcode[BLOCKHASH]" time="0.339" /><testcase classname="tests.opbanning.test_op_banning" name="test_paymaster_banned_opcode[CREATE]" time="0.351" /><testcase classname="tests.opbanning.test_op_banning" name="test_paymaster_banned_opcode[CREATE2]" time="0.373" /><testcase classname="tests.opbanning.test_op_banning" name="test_paymaster_banned_opcode[SELFDESTRUCT]" time="0.363" /><testcase classname="tests.opbanning.test_op_banning" name="test_factory_banned_opcode[GAS]" time="0.524" /><testcase classname="tests.opbanning.test_op_banning" name="test_factory_banned_opcode[NUMBER]" time="0.512" /><testcase classname="tests.opbanning.test_op_banning" name="test_factory_banned_opcode[TIMESTAMP]" time="0.511" /><testcase classname="tests.opbanning.test_op_banning" name="test_factory_banned_opcode[COINBASE]" time="0.543" /><testcase classname="tests.opbanning.test_op_banning" name="test_factory_banned_opcode[DIFFICULTY]" time="0.511" /><testcase classname="tests.opbanning.test_op_banning" name="test_factory_banned_opcode[BASEFEE]" time="0.558" /><testcase classname="tests.opbanning.test_op_banning" name="test_factory_banned_opcode[GASLIMIT]" time="0.513" /><testcase classname="tests.opbanning.test_op_banning" name="test_factory_banned_opcode[GASPRICE]" time="0.532" /><testcase classname="tests.opbanning.test_op_banning" name="test_factory_banned_opcode[SELFBALANCE]" time="0.514" /><testcase classname="tests.opbanning.test_op_banning" name="test_factory_banned_opcode[BALANCE]" time="0.522" /><testcase classname="tests.opbanning.test_op_banning" name="test_factory_banned_opcode[ORIGIN]" time="0.511" /><testcase classname="tests.opbanning.test_op_banning" name="test_factory_banned_opcode[BLOCKHASH]" time="0.529" /><testcase classname="tests.opbanning.test_op_banning" name="test_factory_banned_opcode[CREATE]" time="0.535" /><testcase classname="tests.opbanning.test_op_banning" name="test_factory_banned_opcode[CREATE2]" time="0.531" /><testcase classname="tests.opbanning.test_op_banning" name="test_factory_banned_opcode[SELFDESTRUCT]" time="0.521" /><testcase classname="tests.reputation.test_reputation" name="test_staked_entity_reputation_threshold[with_factory]" time="90.317"><failure message="TypeError: int() can't convert non-string with explicit base">tests/reputation/test_reputation.py:127: in test_staked_entity_reputation_threshold
    assert_reputation_status(
tests/reputation/test_reputation.py:49: in assert_reputation_status
    assert int(reputation.get("status", "-0x1"), 16) == status, (
E   TypeError: int() can't convert non-string with explicit base</failure><system-out>--------------------------------- Captured Log ---------------------------------

--------------------------------- Captured Out ---------------------------------

</system-out><system-err>--------------------------------- Captured Err ---------------------------------

</system-err></testcase><testcase classname="tests.reputation.test_reputation" name="test_staked_entity_reputation_threshold[without_factory]" time="24.397"><failure message="TypeError: int() can't convert non-string with explicit base">tests/reputation/test_reputation.py:134: in test_staked_entity_reputation_threshold
    assert_reputation_status(
tests/reputation/test_reputation.py:49: in assert_reputation_status
    assert int(reputation.get("status", "-0x1"), 16) == status, (
E   TypeError: int() can't convert non-string with explicit base</failure><system-out>--------------------------------- Captured Log ---------------------------------

--------------------------------- Captured Out ---------------------------------

</system-out><system-err>--------------------------------- Captured Err ---------------------------------

</system-err></testcase><testcase classname="tests.rpc.test_eth_chainId" name="test_eth_chainId[]" time="0.019" /><testcase classname="tests.rpc.test_eth_estimateUserOperationGas" name="test_eth_estimateUserOperationGas[]" time="0.190" /><testcase classname="tests.rpc.test_eth_estimateUserOperationGas" name="test_eth_estimateUserOperationGas_execution_revert" time="0.193" /><testcase classname="tests.rpc.test_eth_estimateUserOperationGas" name="test_eth_estimateUserOperationGas_simulation_revert" time="0.204"><failure message="requests.exceptions.ConnectionError: ('Connection aborted.', RemoteDisconnected('Remote end closed connection without response'))">.venv/lib/python3.10/site-packages/urllib3/connectionpool.py:703: in urlopen
    httplib_response = self._make_request(
.venv/lib/python3.10/site-packages/urllib3/connectionpool.py:449: in _make_request
    six.raise_from(e, None)
&lt;string&gt;:3: in raise_from
    ???
.venv/lib/python3.10/site-packages/urllib3/connectionpool.py:444: in _make_request
    httplib_response = conn.getresponse()
/usr/lib/python3.10/http/client.py:1375: in getresponse
    response.begin()
/usr/lib/python3.10/http/client.py:318: in begin
    version, status, reason = self._read_status()
/usr/lib/python3.10/http/client.py:287: in _read_status
    raise RemoteDisconnected("Remote end closed connection without"
E   http.client.RemoteDisconnected: Remote end closed connection without response

During handling of the above exception, another exception occurred:
.venv/lib/python3.10/site-packages/requests/adapters.py:489: in send
    resp = conn.urlopen(
.venv/lib/python3.10/site-packages/urllib3/connectionpool.py:787: in urlopen
    retries = retries.increment(
.venv/lib/python3.10/site-packages/urllib3/util/retry.py:550: in increment
    raise six.reraise(type(error), error, _stacktrace)
.venv/lib/python3.10/site-packages/urllib3/packages/six.py:769: in reraise
    raise value.with_traceback(tb)
.venv/lib/python3.10/site-packages/urllib3/connectionpool.py:703: in urlopen
    httplib_response = self._make_request(
.venv/lib/python3.10/site-packages/urllib3/connectionpool.py:449: in _make_request
    six.raise_from(e, None)
&lt;string&gt;:3: in raise_from
    ???
.venv/lib/python3.10/site-packages/urllib3/connectionpool.py:444: in _make_request
    httplib_response = conn.getresponse()
/usr/lib/python3.10/http/client.py:1375: in getresponse
    response.begin()
/usr/lib/python3.10/http/client.py:318: in begin
    version, status, reason = self._read_status()
/usr/lib/python3.10/http/client.py:287: in _read_status
    raise RemoteDisconnected("Remote end closed connection without"
E   urllib3.exceptions.ProtocolError: ('Connection aborted.', RemoteDisconnected('Remote end closed connection without response'))

During handling of the above exception, another exception occurred:
tests/rpc/test_eth_estimateUserOperationGas.py:36: in test_eth_estimateUserOperationGas_simulation_revert
    ).send()
tests/types.py:69: in send
    requests.post(url, json=asdict(self), timeout=10).json()
.venv/lib/python3.10/site-packages/requests/api.py:115: in post
    return request("post", url, data=data, json=json, **kwargs)
.venv/lib/python3.10/site-packages/requests/api.py:59: in request
    return session.request(method=method, url=url, **kwargs)
.venv/lib/python3.10/site-packages/requests/sessions.py:587: in request
    resp = self.send(prep, **send_kwargs)
.venv/lib/python3.10/site-packages/requests/sessions.py:701: in send
    r = adapter.send(request, **kwargs)
.venv/lib/python3.10/site-packages/requests/adapters.py:547: in send
    raise ConnectionError(err, request=request)
E   requests.exceptions.ConnectionError: ('Connection aborted.', RemoteDisconnected('Remote end closed connection without response'))</failure><system-out>--------------------------------- Captured Log ---------------------------------

--------------------------------- Captured Out ---------------------------------

</system-out><system-err>--------------------------------- Captured Err ---------------------------------

</system-err></testcase><testcase classname="tests.rpc.test_eth_getUserOperationByHash" name="test_eth_getUserOperationByHash[]" time="0.028"><error message="failed on setup with &quot;requests.exceptions.ConnectionError: HTTPConnectionPool(host='localhost', port=3000): Max retries exceeded with url: /rpc (Caused by NewConnectionError('&lt;urllib3.connection.HTTPConnection object at 0x7fc3f7c45bd0&gt;: Failed to establish a new connection: [Errno 111] Connection refused'))&quot;">.venv/lib/python3.10/site-packages/urllib3/connection.py:174: in _new_conn
    conn = connection.create_connection(
.venv/lib/python3.10/site-packages/urllib3/util/connection.py:95: in create_connection
    raise err
.venv/lib/python3.10/site-packages/urllib3/util/connection.py:85: in create_connection
    sock.connect(sa)
E   ConnectionRefusedError: [Errno 111] Connection refused

During handling of the above exception, another exception occurred:
.venv/lib/python3.10/site-packages/urllib3/connectionpool.py:703: in urlopen
    httplib_response = self._make_request(
.venv/lib/python3.10/site-packages/urllib3/connectionpool.py:398: in _make_request
    conn.request(method, url, **httplib_request_kw)
.venv/lib/python3.10/site-packages/urllib3/connection.py:239: in request
    super(HTTPConnection, self).request(method, url, body=body, headers=headers)
/usr/lib/python3.10/http/client.py:1283: in request
    self._send_request(method, url, body, headers, encode_chunked)
/usr/lib/python3.10/http/client.py:1329: in _send_request
    self.endheaders(body, encode_chunked=encode_chunked)
/usr/lib/python3.10/http/client.py:1278: in endheaders
    self._send_output(message_body, encode_chunked=encode_chunked)
/usr/lib/python3.10/http/client.py:1038: in _send_output
    self.send(msg)
/usr/lib/python3.10/http/client.py:976: in send
    self.connect()
.venv/lib/python3.10/site-packages/urllib3/connection.py:205: in connect
    conn = self._new_conn()
.venv/lib/python3.10/site-packages/urllib3/connection.py:186: in _new_conn
    raise NewConnectionError(
E   urllib3.exceptions.NewConnectionError: &lt;urllib3.connection.HTTPConnection object at 0x7fc3f7c45bd0&gt;: Failed to establish a new connection: [Errno 111] Connection refused

During handling of the above exception, another exception occurred:
.venv/lib/python3.10/site-packages/requests/adapters.py:489: in send
    resp = conn.urlopen(
.venv/lib/python3.10/site-packages/urllib3/connectionpool.py:787: in urlopen
    retries = retries.increment(
.venv/lib/python3.10/site-packages/urllib3/util/retry.py:592: in increment
    raise MaxRetryError(_pool, url, error or ResponseError(cause))
E   urllib3.exceptions.MaxRetryError: HTTPConnectionPool(host='localhost', port=3000): Max retries exceeded with url: /rpc (Caused by NewConnectionError('&lt;urllib3.connection.HTTPConnection object at 0x7fc3f7c45bd0&gt;: Failed to establish a new connection: [Errno 111] Connection refused'))

During handling of the above exception, another exception occurred:
tests/conftest.py:106: in execute_user_operation
    userop.send()
tests/types.py:52: in send
    ).send(url)
tests/types.py:69: in send
    requests.post(url, json=asdict(self), timeout=10).json()
.venv/lib/python3.10/site-packages/requests/api.py:115: in post
    return request("post", url, data=data, json=json, **kwargs)
.venv/lib/python3.10/site-packages/requests/api.py:59: in request
    return session.request(method=method, url=url, **kwargs)
.venv/lib/python3.10/site-packages/requests/sessions.py:587: in request
    resp = self.send(prep, **send_kwargs)
.venv/lib/python3.10/site-packages/requests/sessions.py:701: in send
    r = adapter.send(request, **kwargs)
.venv/lib/python3.10/site-packages/requests/adapters.py:565: in send
    raise ConnectionError(e, request=request)
E   requests.exceptions.ConnectionError: HTTPConnectionPool(host='localhost', port=3000): Max retries exceeded with url: /rpc (Caused by NewConnectionError('&lt;urllib3.connection.HTTPConnection object at 0x7fc3f7c45bd0&gt;: Failed to establish a new connection: [Errno 111] Connection refused'))</error></testcase><testcase classname="tests.rpc.test_eth_getUserOperationByHash" name="test_eth_getUserOperationByHash_error" time="0.002"><failure message="requests.exceptions.ConnectionError: HTTPConnectionPool(host='localhost', port=3000): Max retries exceeded with url: /rpc (Caused by NewConnectionError('&lt;urllib3.connection.HTTPConnection object at 0x7fc3f7b17070&gt;: Failed to establish a new connection: [Errno 111] Connection refused'))">.venv/lib/python3.10/site-packages/urllib3/connection.py:174: in _new_conn
    conn = connection.create_connection(
.venv/lib/python3.10/site-packages/urllib3/util/connection.py:95: in create_connection
    raise err
.venv/lib/python3.10/site-packages/urllib3/util/connection.py:85: in create_connection
    sock.connect(sa)
E   ConnectionRefusedError: [Errno 111] Connection refused

During handling of the above exception, another exception occurred:
.venv/lib/python3.10/site-packages/urllib3/connectionpool.py:703: in urlopen
    httplib_response = self._make_request(
.venv/lib/python3.10/site-packages/urllib3/connectionpool.py:398: in _make_request
    conn.request(method, url, **httplib_request_kw)
.venv/lib/python3.10/site-packages/urllib3/connection.py:239: in request
    super(HTTPConnection, self).request(method, url, body=body, headers=headers)
/usr/lib/python3.10/http/client.py:1283: in request
    self._send_request(method, url, body, headers, encode_chunked)
/usr/lib/python3.10/http/client.py:1329: in _send_request
    self.endheaders(body, encode_chunked=encode_chunked)
/usr/lib/python3.10/http/client.py:1278: in endheaders
    self._send_output(message_body, encode_chunked=encode_chunked)
/usr/lib/python3.10/http/client.py:1038: in _send_output
    self.send(msg)
/usr/lib/python3.10/http/client.py:976: in send
    self.connect()
.venv/lib/python3.10/site-packages/urllib3/connection.py:205: in connect
    conn = self._new_conn()
.venv/lib/python3.10/site-packages/urllib3/connection.py:186: in _new_conn
    raise NewConnectionError(
E   urllib3.exceptions.NewConnectionError: &lt;urllib3.connection.HTTPConnection object at 0x7fc3f7b17070&gt;: Failed to establish a new connection: [Errno 111] Connection refused

During handling of the above exception, another exception occurred:
.venv/lib/python3.10/site-packages/requests/adapters.py:489: in send
    resp = conn.urlopen(
.venv/lib/python3.10/site-packages/urllib3/connectionpool.py:787: in urlopen
    retries = retries.increment(
.venv/lib/python3.10/site-packages/urllib3/util/retry.py:592: in increment
    raise MaxRetryError(_pool, url, error or ResponseError(cause))
E   urllib3.exceptions.MaxRetryError: HTTPConnectionPool(host='localhost', port=3000): Max retries exceeded with url: /rpc (Caused by NewConnectionError('&lt;urllib3.connection.HTTPConnection object at 0x7fc3f7b17070&gt;: Failed to establish a new connection: [Errno 111] Connection refused'))

During handling of the above exception, another exception occurred:
tests/rpc/test_eth_getUserOperationByHash.py:27: in test_eth_getUserOperationByHash_error
    response = RPCRequest(method="eth_getUserOperationByHash", params=[""]).send()
tests/types.py:69: in send
    requests.post(url, json=asdict(self), timeout=10).json()
.venv/lib/python3.10/site-packages/requests/api.py:115: in post
    return request("post", url, data=data, json=json, **kwargs)
.venv/lib/python3.10/site-packages/requests/api.py:59: in request
    return session.request(method=method, url=url, **kwargs)
.venv/lib/python3.10/site-packages/requests/sessions.py:587: in request
    resp = self.send(prep, **send_kwargs)
.venv/lib/python3.10/site-packages/requests/sessions.py:701: in send
    r = adapter.send(request, **kwargs)
.venv/lib/python3.10/site-packages/requests/adapters.py:565: in send
    raise ConnectionError(e, request=request)
E   requests.exceptions.ConnectionError: HTTPConnectionPool(host='localhost', port=3000): Max retries exceeded with url: /rpc (Caused by NewConnectionError('&lt;urllib3.connection.HTTPConnection object at 0x7fc3f7b17070&gt;: Failed to establish a new connection: [Errno 111] Connection refused'))</failure><system-out>--------------------------------- Captured Log ---------------------------------

--------------------------------- Captured Out ---------------------------------

</system-out><system-err>--------------------------------- Captured Err ---------------------------------

</system-err></testcase><testcase classname="tests.rpc.test_eth_getUserOperationReceipt" name="test_eth_getUserOperationReceipt[]" time="0.070"><error message="failed on setup with &quot;requests.exceptions.ConnectionError: HTTPConnectionPool(host='localhost', port=3000): Max retries exceeded with url: /rpc (Caused by NewConnectionError('&lt;urllib3.connection.HTTPConnection object at 0x7fc3f7b68580&gt;: Failed to establish a new connection: [Errno 111] Connection refused'))&quot;">.venv/lib/python3.10/site-packages/urllib3/connection.py:174: in _new_conn
    conn = connection.create_connection(
.venv/lib/python3.10/site-packages/urllib3/util/connection.py:95: in create_connection
    raise err
.venv/lib/python3.10/site-packages/urllib3/util/connection.py:85: in create_connection
    sock.connect(sa)
E   ConnectionRefusedError: [Errno 111] Connection refused

During handling of the above exception, another exception occurred:
.venv/lib/python3.10/site-packages/urllib3/connectionpool.py:703: in urlopen
    httplib_response = self._make_request(
.venv/lib/python3.10/site-packages/urllib3/connectionpool.py:398: in _make_request
    conn.request(method, url, **httplib_request_kw)
.venv/lib/python3.10/site-packages/urllib3/connection.py:239: in request
    super(HTTPConnection, self).request(method, url, body=body, headers=headers)
/usr/lib/python3.10/http/client.py:1283: in request
    self._send_request(method, url, body, headers, encode_chunked)
/usr/lib/python3.10/http/client.py:1329: in _send_request
    self.endheaders(body, encode_chunked=encode_chunked)
/usr/lib/python3.10/http/client.py:1278: in endheaders
    self._send_output(message_body, encode_chunked=encode_chunked)
/usr/lib/python3.10/http/client.py:1038: in _send_output
    self.send(msg)
/usr/lib/python3.10/http/client.py:976: in send
    self.connect()
.venv/lib/python3.10/site-packages/urllib3/connection.py:205: in connect
    conn = self._new_conn()
.venv/lib/python3.10/site-packages/urllib3/connection.py:186: in _new_conn
    raise NewConnectionError(
E   urllib3.exceptions.NewConnectionError: &lt;urllib3.connection.HTTPConnection object at 0x7fc3f7b68580&gt;: Failed to establish a new connection: [Errno 111] Connection refused

During handling of the above exception, another exception occurred:
.venv/lib/python3.10/site-packages/requests/adapters.py:489: in send
    resp = conn.urlopen(
.venv/lib/python3.10/site-packages/urllib3/connectionpool.py:787: in urlopen
    retries = retries.increment(
.venv/lib/python3.10/site-packages/urllib3/util/retry.py:592: in increment
    raise MaxRetryError(_pool, url, error or ResponseError(cause))
E   urllib3.exceptions.MaxRetryError: HTTPConnectionPool(host='localhost', port=3000): Max retries exceeded with url: /rpc (Caused by NewConnectionError('&lt;urllib3.connection.HTTPConnection object at 0x7fc3f7b68580&gt;: Failed to establish a new connection: [Errno 111] Connection refused'))

During handling of the above exception, another exception occurred:
tests/conftest.py:106: in execute_user_operation
    userop.send()
tests/types.py:52: in send
    ).send(url)
tests/types.py:69: in send
    requests.post(url, json=asdict(self), timeout=10).json()
.venv/lib/python3.10/site-packages/requests/api.py:115: in post
    return request("post", url, data=data, json=json, **kwargs)
.venv/lib/python3.10/site-packages/requests/api.py:59: in request
    return session.request(method=method, url=url, **kwargs)
.venv/lib/python3.10/site-packages/requests/sessions.py:587: in request
    resp = self.send(prep, **send_kwargs)
.venv/lib/python3.10/site-packages/requests/sessions.py:701: in send
    r = adapter.send(request, **kwargs)
.venv/lib/python3.10/site-packages/requests/adapters.py:565: in send
    raise ConnectionError(e, request=request)
E   requests.exceptions.ConnectionError: HTTPConnectionPool(host='localhost', port=3000): Max retries exceeded with url: /rpc (Caused by NewConnectionError('&lt;urllib3.connection.HTTPConnection object at 0x7fc3f7b68580&gt;: Failed to establish a new connection: [Errno 111] Connection refused'))</error></testcase><testcase classname="tests.rpc.test_eth_getUserOperationReceipt" name="test_eth_getUserOperationReceipt_error" time="0.002"><failure message="requests.exceptions.ConnectionError: HTTPConnectionPool(host='localhost', port=3000): Max retries exceeded with url: /rpc (Caused by NewConnectionError('&lt;urllib3.connection.HTTPConnection object at 0x7fc3f7ddd330&gt;: Failed to establish a new connection: [Errno 111] Connection refused'))">.venv/lib/python3.10/site-packages/urllib3/connection.py:174: in _new_conn
    conn = connection.create_connection(
.venv/lib/python3.10/site-packages/urllib3/util/connection.py:95: in create_connection
    raise err
.venv/lib/python3.10/site-packages/urllib3/util/connection.py:85: in create_connection
    sock.connect(sa)
E   ConnectionRefusedError: [Errno 111] Connection refused

During handling of the above exception, another exception occurred:
.venv/lib/python3.10/site-packages/urllib3/connectionpool.py:703: in urlopen
    httplib_response = self._make_request(
.venv/lib/python3.10/site-packages/urllib3/connectionpool.py:398: in _make_request
    conn.request(method, url, **httplib_request_kw)
.venv/lib/python3.10/site-packages/urllib3/connection.py:239: in request
    super(HTTPConnection, self).request(method, url, body=body, headers=headers)
/usr/lib/python3.10/http/client.py:1283: in request
    self._send_request(method, url, body, headers, encode_chunked)
/usr/lib/python3.10/http/client.py:1329: in _send_request
    self.endheaders(body, encode_chunked=encode_chunked)
/usr/lib/python3.10/http/client.py:1278: in endheaders
    self._send_output(message_body, encode_chunked=encode_chunked)
/usr/lib/python3.10/http/client.py:1038: in _send_output
    self.send(msg)
/usr/lib/python3.10/http/client.py:976: in send
    self.connect()
.venv/lib/python3.10/site-packages/urllib3/connection.py:205: in connect
    conn = self._new_conn()
.venv/lib/python3.10/site-packages/urllib3/connection.py:186: in _new_conn
    raise NewConnectionError(
E   urllib3.exceptions.NewConnectionError: &lt;urllib3.connection.HTTPConnection object at 0x7fc3f7ddd330&gt;: Failed to establish a new connection: [Errno 111] Connection refused

During handling of the above exception, another exception occurred:
.venv/lib/python3.10/site-packages/requests/adapters.py:489: in send
    resp = conn.urlopen(
.venv/lib/python3.10/site-packages/urllib3/connectionpool.py:787: in urlopen
    retries = retries.increment(
.venv/lib/python3.10/site-packages/urllib3/util/retry.py:592: in increment
    raise MaxRetryError(_pool, url, error or ResponseError(cause))
E   urllib3.exceptions.MaxRetryError: HTTPConnectionPool(host='localhost', port=3000): Max retries exceeded with url: /rpc (Caused by NewConnectionError('&lt;urllib3.connection.HTTPConnection object at 0x7fc3f7ddd330&gt;: Failed to establish a new connection: [Errno 111] Connection refused'))

During handling of the above exception, another exception occurred:
tests/rpc/test_eth_getUserOperationReceipt.py:25: in test_eth_getUserOperationReceipt_error
    response = RPCRequest(method="eth_getUserOperationReceipt", params=[""]).send()
tests/types.py:69: in send
    requests.post(url, json=asdict(self), timeout=10).json()
.venv/lib/python3.10/site-packages/requests/api.py:115: in post
    return request("post", url, data=data, json=json, **kwargs)
.venv/lib/python3.10/site-packages/requests/api.py:59: in request
    return session.request(method=method, url=url, **kwargs)
.venv/lib/python3.10/site-packages/requests/sessions.py:587: in request
    resp = self.send(prep, **send_kwargs)
.venv/lib/python3.10/site-packages/requests/sessions.py:701: in send
    r = adapter.send(request, **kwargs)
.venv/lib/python3.10/site-packages/requests/adapters.py:565: in send
    raise ConnectionError(e, request=request)
E   requests.exceptions.ConnectionError: HTTPConnectionPool(host='localhost', port=3000): Max retries exceeded with url: /rpc (Caused by NewConnectionError('&lt;urllib3.connection.HTTPConnection object at 0x7fc3f7ddd330&gt;: Failed to establish a new connection: [Errno 111] Connection refused'))</failure><system-out>--------------------------------- Captured Log ---------------------------------

--------------------------------- Captured Out ---------------------------------

</system-out><system-err>--------------------------------- Captured Err ---------------------------------

</system-err></testcase><testcase classname="tests.rpc.test_eth_sendUserOperation" name="test_eth_sendUserOperation[]" time="0.034"><failure message="requests.exceptions.ConnectionError: HTTPConnectionPool(host='localhost', port=3000): Max retries exceeded with url: /rpc (Caused by NewConnectionError('&lt;urllib3.connection.HTTPConnection object at 0x7fc3f7b16020&gt;: Failed to establish a new connection: [Errno 111] Connection refused'))">.venv/lib/python3.10/site-packages/urllib3/connection.py:174: in _new_conn
    conn = connection.create_connection(
.venv/lib/python3.10/site-packages/urllib3/util/connection.py:95: in create_connection
    raise err
.venv/lib/python3.10/site-packages/urllib3/util/connection.py:85: in create_connection
    sock.connect(sa)
E   ConnectionRefusedError: [Errno 111] Connection refused

During handling of the above exception, another exception occurred:
.venv/lib/python3.10/site-packages/urllib3/connectionpool.py:703: in urlopen
    httplib_response = self._make_request(
.venv/lib/python3.10/site-packages/urllib3/connectionpool.py:398: in _make_request
    conn.request(method, url, **httplib_request_kw)
.venv/lib/python3.10/site-packages/urllib3/connection.py:239: in request
    super(HTTPConnection, self).request(method, url, body=body, headers=headers)
/usr/lib/python3.10/http/client.py:1283: in request
    self._send_request(method, url, body, headers, encode_chunked)
/usr/lib/python3.10/http/client.py:1329: in _send_request
    self.endheaders(body, encode_chunked=encode_chunked)
/usr/lib/python3.10/http/client.py:1278: in endheaders
    self._send_output(message_body, encode_chunked=encode_chunked)
/usr/lib/python3.10/http/client.py:1038: in _send_output
    self.send(msg)
/usr/lib/python3.10/http/client.py:976: in send
    self.connect()
.venv/lib/python3.10/site-packages/urllib3/connection.py:205: in connect
    conn = self._new_conn()
.venv/lib/python3.10/site-packages/urllib3/connection.py:186: in _new_conn
    raise NewConnectionError(
E   urllib3.exceptions.NewConnectionError: &lt;urllib3.connection.HTTPConnection object at 0x7fc3f7b16020&gt;: Failed to establish a new connection: [Errno 111] Connection refused

During handling of the above exception, another exception occurred:
.venv/lib/python3.10/site-packages/requests/adapters.py:489: in send
    resp = conn.urlopen(
.venv/lib/python3.10/site-packages/urllib3/connectionpool.py:787: in urlopen
    retries = retries.increment(
.venv/lib/python3.10/site-packages/urllib3/util/retry.py:592: in increment
    raise MaxRetryError(_pool, url, error or ResponseError(cause))
E   urllib3.exceptions.MaxRetryError: HTTPConnectionPool(host='localhost', port=3000): Max retries exceeded with url: /rpc (Caused by NewConnectionError('&lt;urllib3.connection.HTTPConnection object at 0x7fc3f7b16020&gt;: Failed to establish a new connection: [Errno 111] Connection refused'))

During handling of the above exception, another exception occurred:
tests/rpc/test_eth_sendUserOperation.py:16: in test_eth_sendUserOperation
    response = userop.send()
tests/types.py:52: in send
    ).send(url)
tests/types.py:69: in send
    requests.post(url, json=asdict(self), timeout=10).json()
.venv/lib/python3.10/site-packages/requests/api.py:115: in post
    return request("post", url, data=data, json=json, **kwargs)
.venv/lib/python3.10/site-packages/requests/api.py:59: in request
    return session.request(method=method, url=url, **kwargs)
.venv/lib/python3.10/site-packages/requests/sessions.py:587: in request
    resp = self.send(prep, **send_kwargs)
.venv/lib/python3.10/site-packages/requests/sessions.py:701: in send
    r = adapter.send(request, **kwargs)
.venv/lib/python3.10/site-packages/requests/adapters.py:565: in send
    raise ConnectionError(e, request=request)
E   requests.exceptions.ConnectionError: HTTPConnectionPool(host='localhost', port=3000): Max retries exceeded with url: /rpc (Caused by NewConnectionError('&lt;urllib3.connection.HTTPConnection object at 0x7fc3f7b16020&gt;: Failed to establish a new connection: [Errno 111] Connection refused'))</failure><system-out>--------------------------------- Captured Log ---------------------------------

--------------------------------- Captured Out ---------------------------------

</system-out><system-err>--------------------------------- Captured Err ---------------------------------

</system-err></testcase><testcase classname="tests.rpc.test_eth_sendUserOperation" name="test_eth_sendUserOperation_revert" time="0.035"><failure message="requests.exceptions.ConnectionError: HTTPConnectionPool(host='localhost', port=3000): Max retries exceeded with url: /rpc (Caused by NewConnectionError('&lt;urllib3.connection.HTTPConnection object at 0x7fc3f839a680&gt;: Failed to establish a new connection: [Errno 111] Connection refused'))">.venv/lib/python3.10/site-packages/urllib3/connection.py:174: in _new_conn
    conn = connection.create_connection(
.venv/lib/python3.10/site-packages/urllib3/util/connection.py:95: in create_connection
    raise err
.venv/lib/python3.10/site-packages/urllib3/util/connection.py:85: in create_connection
    sock.connect(sa)
E   ConnectionRefusedError: [Errno 111] Connection refused

During handling of the above exception, another exception occurred:
.venv/lib/python3.10/site-packages/urllib3/connectionpool.py:703: in urlopen
    httplib_response = self._make_request(
.venv/lib/python3.10/site-packages/urllib3/connectionpool.py:398: in _make_request
    conn.request(method, url, **httplib_request_kw)
.venv/lib/python3.10/site-packages/urllib3/connection.py:239: in request
    super(HTTPConnection, self).request(method, url, body=body, headers=headers)
/usr/lib/python3.10/http/client.py:1283: in request
    self._send_request(method, url, body, headers, encode_chunked)
/usr/lib/python3.10/http/client.py:1329: in _send_request
    self.endheaders(body, encode_chunked=encode_chunked)
/usr/lib/python3.10/http/client.py:1278: in endheaders
    self._send_output(message_body, encode_chunked=encode_chunked)
/usr/lib/python3.10/http/client.py:1038: in _send_output
    self.send(msg)
/usr/lib/python3.10/http/client.py:976: in send
    self.connect()
.venv/lib/python3.10/site-packages/urllib3/connection.py:205: in connect
    conn = self._new_conn()
.venv/lib/python3.10/site-packages/urllib3/connection.py:186: in _new_conn
    raise NewConnectionError(
E   urllib3.exceptions.NewConnectionError: &lt;urllib3.connection.HTTPConnection object at 0x7fc3f839a680&gt;: Failed to establish a new connection: [Errno 111] Connection refused

During handling of the above exception, another exception occurred:
.venv/lib/python3.10/site-packages/requests/adapters.py:489: in send
    resp = conn.urlopen(
.venv/lib/python3.10/site-packages/urllib3/connectionpool.py:787: in urlopen
    retries = retries.increment(
.venv/lib/python3.10/site-packages/urllib3/util/retry.py:592: in increment
    raise MaxRetryError(_pool, url, error or ResponseError(cause))
E   urllib3.exceptions.MaxRetryError: HTTPConnectionPool(host='localhost', port=3000): Max retries exceeded with url: /rpc (Caused by NewConnectionError('&lt;urllib3.connection.HTTPConnection object at 0x7fc3f839a680&gt;: Failed to establish a new connection: [Errno 111] Connection refused'))

During handling of the above exception, another exception occurred:
tests/rpc/test_eth_sendUserOperation.py:28: in test_eth_sendUserOperation_revert
    response = bad_sig_userop.send()
tests/types.py:52: in send
    ).send(url)
tests/types.py:69: in send
    requests.post(url, json=asdict(self), timeout=10).json()
.venv/lib/python3.10/site-packages/requests/api.py:115: in post
    return request("post", url, data=data, json=json, **kwargs)
.venv/lib/python3.10/site-packages/requests/api.py:59: in request
    return session.request(method=method, url=url, **kwargs)
.venv/lib/python3.10/site-packages/requests/sessions.py:587: in request
    resp = self.send(prep, **send_kwargs)
.venv/lib/python3.10/site-packages/requests/sessions.py:701: in send
    r = adapter.send(request, **kwargs)
.venv/lib/python3.10/site-packages/requests/adapters.py:565: in send
    raise ConnectionError(e, request=request)
E   requests.exceptions.ConnectionError: HTTPConnectionPool(host='localhost', port=3000): Max retries exceeded with url: /rpc (Caused by NewConnectionError('&lt;urllib3.connection.HTTPConnection object at 0x7fc3f839a680&gt;: Failed to establish a new connection: [Errno 111] Connection refused'))</failure><system-out>--------------------------------- Captured Log ---------------------------------

--------------------------------- Captured Out ---------------------------------

</system-out><system-err>--------------------------------- Captured Err ---------------------------------

</system-err></testcase><testcase classname="tests.rpc.test_eth_sendUserOperation" name="test_eth_sendUserOperation_invalid_signature" time="0.030"><failure message="requests.exceptions.ConnectionError: HTTPConnectionPool(host='localhost', port=3000): Max retries exceeded with url: /rpc (Caused by NewConnectionError('&lt;urllib3.connection.HTTPConnection object at 0x7fc3f7f65930&gt;: Failed to establish a new connection: [Errno 111] Connection refused'))">.venv/lib/python3.10/site-packages/urllib3/connection.py:174: in _new_conn
    conn = connection.create_connection(
.venv/lib/python3.10/site-packages/urllib3/util/connection.py:95: in create_connection
    raise err
.venv/lib/python3.10/site-packages/urllib3/util/connection.py:85: in create_connection
    sock.connect(sa)
E   ConnectionRefusedError: [Errno 111] Connection refused

During handling of the above exception, another exception occurred:
.venv/lib/python3.10/site-packages/urllib3/connectionpool.py:703: in urlopen
    httplib_response = self._make_request(
.venv/lib/python3.10/site-packages/urllib3/connectionpool.py:398: in _make_request
    conn.request(method, url, **httplib_request_kw)
.venv/lib/python3.10/site-packages/urllib3/connection.py:239: in request
    super(HTTPConnection, self).request(method, url, body=body, headers=headers)
/usr/lib/python3.10/http/client.py:1283: in request
    self._send_request(method, url, body, headers, encode_chunked)
/usr/lib/python3.10/http/client.py:1329: in _send_request
    self.endheaders(body, encode_chunked=encode_chunked)
/usr/lib/python3.10/http/client.py:1278: in endheaders
    self._send_output(message_body, encode_chunked=encode_chunked)
/usr/lib/python3.10/http/client.py:1038: in _send_output
    self.send(msg)
/usr/lib/python3.10/http/client.py:976: in send
    self.connect()
.venv/lib/python3.10/site-packages/urllib3/connection.py:205: in connect
    conn = self._new_conn()
.venv/lib/python3.10/site-packages/urllib3/connection.py:186: in _new_conn
    raise NewConnectionError(
E   urllib3.exceptions.NewConnectionError: &lt;urllib3.connection.HTTPConnection object at 0x7fc3f7f65930&gt;: Failed to establish a new connection: [Errno 111] Connection refused

During handling of the above exception, another exception occurred:
.venv/lib/python3.10/site-packages/requests/adapters.py:489: in send
    resp = conn.urlopen(
.venv/lib/python3.10/site-packages/urllib3/connectionpool.py:787: in urlopen
    retries = retries.increment(
.venv/lib/python3.10/site-packages/urllib3/util/retry.py:592: in increment
    raise MaxRetryError(_pool, url, error or ResponseError(cause))
E   urllib3.exceptions.MaxRetryError: HTTPConnectionPool(host='localhost', port=3000): Max retries exceeded with url: /rpc (Caused by NewConnectionError('&lt;urllib3.connection.HTTPConnection object at 0x7fc3f7f65930&gt;: Failed to establish a new connection: [Errno 111] Connection refused'))

During handling of the above exception, another exception occurred:
tests/rpc/test_eth_sendUserOperation.py:39: in test_eth_sendUserOperation_invalid_signature
    invalid_sig_userop.send(),
tests/types.py:52: in send
    ).send(url)
tests/types.py:69: in send
    requests.post(url, json=asdict(self), timeout=10).json()
.venv/lib/python3.10/site-packages/requests/api.py:115: in post
    return request("post", url, data=data, json=json, **kwargs)
.venv/lib/python3.10/site-packages/requests/api.py:59: in request
    return session.request(method=method, url=url, **kwargs)
.venv/lib/python3.10/site-packages/requests/sessions.py:587: in request
    resp = self.send(prep, **send_kwargs)
.venv/lib/python3.10/site-packages/requests/sessions.py:701: in send
    r = adapter.send(request, **kwargs)
.venv/lib/python3.10/site-packages/requests/adapters.py:565: in send
    raise ConnectionError(e, request=request)
E   requests.exceptions.ConnectionError: HTTPConnectionPool(host='localhost', port=3000): Max retries exceeded with url: /rpc (Caused by NewConnectionError('&lt;urllib3.connection.HTTPConnection object at 0x7fc3f7f65930&gt;: Failed to establish a new connection: [Errno 111] Connection refused'))</failure><system-out>--------------------------------- Captured Log ---------------------------------

--------------------------------- Captured Out ---------------------------------

</system-out><system-err>--------------------------------- Captured Err ---------------------------------

</system-err></testcase><testcase classname="tests.rpc.test_eth_supportedEntryPoints" name="test_eth_supportedEntryPoints[]" time="0.014"><failure message="requests.exceptions.ConnectionError: HTTPConnectionPool(host='localhost', port=3000): Max retries exceeded with url: /rpc (Caused by NewConnectionError('&lt;urllib3.connection.HTTPConnection object at 0x7fc3f7fec3a0&gt;: Failed to establish a new connection: [Errno 111] Connection refused'))">.venv/lib/python3.10/site-packages/urllib3/connection.py:174: in _new_conn
    conn = connection.create_connection(
.venv/lib/python3.10/site-packages/urllib3/util/connection.py:95: in create_connection
    raise err
.venv/lib/python3.10/site-packages/urllib3/util/connection.py:85: in create_connection
    sock.connect(sa)
E   ConnectionRefusedError: [Errno 111] Connection refused

During handling of the above exception, another exception occurred:
.venv/lib/python3.10/site-packages/urllib3/connectionpool.py:703: in urlopen
    httplib_response = self._make_request(
.venv/lib/python3.10/site-packages/urllib3/connectionpool.py:398: in _make_request
    conn.request(method, url, **httplib_request_kw)
.venv/lib/python3.10/site-packages/urllib3/connection.py:239: in request
    super(HTTPConnection, self).request(method, url, body=body, headers=headers)
/usr/lib/python3.10/http/client.py:1283: in request
    self._send_request(method, url, body, headers, encode_chunked)
/usr/lib/python3.10/http/client.py:1329: in _send_request
    self.endheaders(body, encode_chunked=encode_chunked)
/usr/lib/python3.10/http/client.py:1278: in endheaders
    self._send_output(message_body, encode_chunked=encode_chunked)
/usr/lib/python3.10/http/client.py:1038: in _send_output
    self.send(msg)
/usr/lib/python3.10/http/client.py:976: in send
    self.connect()
.venv/lib/python3.10/site-packages/urllib3/connection.py:205: in connect
    conn = self._new_conn()
.venv/lib/python3.10/site-packages/urllib3/connection.py:186: in _new_conn
    raise NewConnectionError(
E   urllib3.exceptions.NewConnectionError: &lt;urllib3.connection.HTTPConnection object at 0x7fc3f7fec3a0&gt;: Failed to establish a new connection: [Errno 111] Connection refused

During handling of the above exception, another exception occurred:
.venv/lib/python3.10/site-packages/requests/adapters.py:489: in send
    resp = conn.urlopen(
.venv/lib/python3.10/site-packages/urllib3/connectionpool.py:787: in urlopen
    retries = retries.increment(
.venv/lib/python3.10/site-packages/urllib3/util/retry.py:592: in increment
    raise MaxRetryError(_pool, url, error or ResponseError(cause))
E   urllib3.exceptions.MaxRetryError: HTTPConnectionPool(host='localhost', port=3000): Max retries exceeded with url: /rpc (Caused by NewConnectionError('&lt;urllib3.connection.HTTPConnection object at 0x7fc3f7fec3a0&gt;: Failed to establish a new connection: [Errno 111] Connection refused'))

During handling of the above exception, another exception occurred:
tests/rpc/test_eth_supportedEntryPoints.py:8: in test_eth_supportedEntryPoints
    response = RPCRequest(method="eth_supportedEntryPoints").send(CommandLineArgs.url)
tests/types.py:69: in send
    requests.post(url, json=asdict(self), timeout=10).json()
.venv/lib/python3.10/site-packages/requests/api.py:115: in post
    return request("post", url, data=data, json=json, **kwargs)
.venv/lib/python3.10/site-packages/requests/api.py:59: in request
    return session.request(method=method, url=url, **kwargs)
.venv/lib/python3.10/site-packages/requests/sessions.py:587: in request
    resp = self.send(prep, **send_kwargs)
.venv/lib/python3.10/site-packages/requests/sessions.py:701: in send
    r = adapter.send(request, **kwargs)
.venv/lib/python3.10/site-packages/requests/adapters.py:565: in send
    raise ConnectionError(e, request=request)
E   requests.exceptions.ConnectionError: HTTPConnectionPool(host='localhost', port=3000): Max retries exceeded with url: /rpc (Caused by NewConnectionError('&lt;urllib3.connection.HTTPConnection object at 0x7fc3f7fec3a0&gt;: Failed to establish a new connection: [Errno 111] Connection refused'))</failure><system-out>--------------------------------- Captured Log ---------------------------------

--------------------------------- Captured Out ---------------------------------

</system-out><system-err>--------------------------------- Captured Err ---------------------------------

</system-err></testcase></testsuite></testsuites>