<?xml version="1.0" encoding="utf-8"?><testsuites><testsuite name="silius" errors="1" failures="18" skipped="0" tests="167" time="157.453" timestamp="2023-10-08T16:16:01.380534" hostname="fv-az306-7"><testcase classname="tests.bundle.test_bundle" name="test_bundle_replace_op[only_priority_fee_bump]" time="0.206" /><testcase classname="tests.bundle.test_bundle" name="test_bundle_replace_op[only_max_fee_bump]" time="0.180" /><testcase classname="tests.bundle.test_bundle" name="test_bundle_replace_op[with_same_fee]" time="0.181" /><testcase classname="tests.bundle.test_bundle" name="test_bundle_replace_op[with_less_fee]" time="0.177" /><testcase classname="tests.bundle.test_bundle" name="test_bundle_replace_op[fee_bump_below_threshold]" time="0.174" /><testcase classname="tests.bundle.test_bundle" name="test_bundle_replace_op[fee_bump_at_threshold]" time="0.438" /><testcase classname="tests.bundle.test_bundle" name="test_bundle_replace_op[fee_bump_above_threshold]" time="0.307" /><testcase classname="tests.bundle.test_bundle" name="test_mempool_reputation_rules_all_entities[SREP-020-banned-entity-not-allowed-banned-sender]" time="0.338"><failure message="AttributeError: 'Error' object has no attribute 'result'">tests/bundle/test_bundle.py:148: in test_mempool_reputation_rules_all_entities
    set_reputation(
tests/utils.py:200: in set_reputation
    )
E   AttributeError: 'Error' object has no attribute 'result'</failure><system-out>--------------------------------- Captured Log ---------------------------------

--------------------------------- Captured Out ---------------------------------

</system-out><system-err>--------------------------------- Captured Err ---------------------------------

</system-err></testcase><testcase classname="tests.bundle.test_bundle" name="test_mempool_reputation_rules_all_entities[SREP-020-banned-entity-not-allowed-banned-paymaster]" time="0.205"><failure message="AttributeError: 'Error' object has no attribute 'result'">tests/bundle/test_bundle.py:154: in test_mempool_reputation_rules_all_entities
    set_reputation(
tests/utils.py:200: in set_reputation
    )
E   AttributeError: 'Error' object has no attribute 'result'</failure><system-out>--------------------------------- Captured Log ---------------------------------

--------------------------------- Captured Out ---------------------------------

</system-out><system-err>--------------------------------- Captured Err ---------------------------------

</system-err></testcase><testcase classname="tests.bundle.test_bundle" name="test_mempool_reputation_rules_all_entities[SREP-020-banned-entity-not-allowed-banned-factory]" time="0.195"><failure message="AttributeError: 'Error' object has no attribute 'result'">tests/bundle/test_bundle.py:160: in test_mempool_reputation_rules_all_entities
    set_reputation(
tests/utils.py:200: in set_reputation
    )
E   AttributeError: 'Error' object has no attribute 'result'</failure><system-out>--------------------------------- Captured Log ---------------------------------

--------------------------------- Captured Out ---------------------------------

</system-out><system-err>--------------------------------- Captured Err ---------------------------------

</system-err></testcase><testcase classname="tests.bundle.test_bundle" name="test_mempool_reputation_rules_all_entities[SREP-030-throttled-entity-allowed-a-little-throttled-sender]" time="0.201"><failure message="AttributeError: 'Error' object has no attribute 'result'">tests/bundle/test_bundle.py:148: in test_mempool_reputation_rules_all_entities
    set_reputation(
tests/utils.py:200: in set_reputation
    )
E   AttributeError: 'Error' object has no attribute 'result'</failure><system-out>--------------------------------- Captured Log ---------------------------------

--------------------------------- Captured Out ---------------------------------

</system-out><system-err>--------------------------------- Captured Err ---------------------------------

</system-err></testcase><testcase classname="tests.bundle.test_bundle" name="test_mempool_reputation_rules_all_entities[SREP-030-throttled-entity-allowed-a-little-throttled-paymaster]" time="0.194"><failure message="AttributeError: 'Error' object has no attribute 'result'">tests/bundle/test_bundle.py:154: in test_mempool_reputation_rules_all_entities
    set_reputation(
tests/utils.py:200: in set_reputation
    )
E   AttributeError: 'Error' object has no attribute 'result'</failure><system-out>--------------------------------- Captured Log ---------------------------------

--------------------------------- Captured Out ---------------------------------

</system-out><system-err>--------------------------------- Captured Err ---------------------------------

</system-err></testcase><testcase classname="tests.bundle.test_bundle" name="test_mempool_reputation_rules_all_entities[SREP-030-throttled-entity-allowed-a-little-throttled-factory]" time="0.191"><failure message="AttributeError: 'Error' object has no attribute 'result'">tests/bundle/test_bundle.py:160: in test_mempool_reputation_rules_all_entities
    set_reputation(
tests/utils.py:200: in set_reputation
    )
E   AttributeError: 'Error' object has no attribute 'result'</failure><system-out>--------------------------------- Captured Log ---------------------------------

--------------------------------- Captured Out ---------------------------------

</system-out><system-err>--------------------------------- Captured Err ---------------------------------

</system-err></testcase><testcase classname="tests.bundle.test_bundle" name="test_mempool_reputation_rules_all_entities[UREP-010 UREP-020-unstaked-entity-allowed-function-unstaked-sender]" time="0.229"><failure message="AttributeError: 'Error' object has no attribute 'result'">tests/bundle/test_bundle.py:148: in test_mempool_reputation_rules_all_entities
    set_reputation(
tests/utils.py:200: in set_reputation
    )
E   AttributeError: 'Error' object has no attribute 'result'</failure><system-out>--------------------------------- Captured Log ---------------------------------

--------------------------------- Captured Out ---------------------------------

</system-out><system-err>--------------------------------- Captured Err ---------------------------------

</system-err></testcase><testcase classname="tests.bundle.test_bundle" name="test_mempool_reputation_rules_all_entities[UREP-010 UREP-020-unstaked-entity-allowed-function-unstaked-paymaster]" time="0.196"><failure message="AttributeError: 'Error' object has no attribute 'result'">tests/bundle/test_bundle.py:154: in test_mempool_reputation_rules_all_entities
    set_reputation(
tests/utils.py:200: in set_reputation
    )
E   AttributeError: 'Error' object has no attribute 'result'</failure><system-out>--------------------------------- Captured Log ---------------------------------

--------------------------------- Captured Out ---------------------------------

</system-out><system-err>--------------------------------- Captured Err ---------------------------------

</system-err></testcase><testcase classname="tests.bundle.test_bundle" name="test_mempool_reputation_rules_all_entities[UREP-010 UREP-020-unstaked-entity-allowed-function-unstaked-factory]" time="0.193"><failure message="AttributeError: 'Error' object has no attribute 'result'">tests/bundle/test_bundle.py:160: in test_mempool_reputation_rules_all_entities
    set_reputation(
tests/utils.py:200: in set_reputation
    )
E   AttributeError: 'Error' object has no attribute 'result'</failure><system-out>--------------------------------- Captured Log ---------------------------------

--------------------------------- Captured Out ---------------------------------

</system-out><system-err>--------------------------------- Captured Err ---------------------------------

</system-err></testcase><testcase classname="tests.bundle.test_bundle" name="test_max_allowed_ops_unstaked_sender" time="0.856" /><testcase classname="tests.bundle.test_bundle" name="test_max_allowed_ops_staked_sender" time="1.116" /><testcase classname="tests.bundle.test_bundle" name="test_ban_user_op_access_other_ops_sender_in_bundle" time="0.935" /><testcase classname="tests.bundle.test_bundle" name="test_ban_user_sender_double_role_in_bundle" time="0.439"><failure message="Exception: expected error object, got:&#10;Ok(result='0xeee5d5f82f2351a4cc0b48098e14cd44efbe874cc53f4f9699c2de5f74dbea13', id=113)">tests/utils.py:115: in assert_rpc_error
    assert response.code == code
E   AttributeError: 'Ok' object has no attribute 'code'

The above exception was the direct cause of the following exception:
tests/bundle/test_bundle.py:359: in test_ban_user_sender_double_role_in_bundle
    assert_rpc_error(
tests/utils.py:118: in assert_rpc_error
    raise Exception(f"expected error object, got:\n{response}") from exc
E   Exception: expected error object, got:
E   Ok(result='0xeee5d5f82f2351a4cc0b48098e14cd44efbe874cc53f4f9699c2de5f74dbea13', id=113)</failure><system-out>--------------------------------- Captured Log ---------------------------------

--------------------------------- Captured Out ---------------------------------

</system-out><system-err>--------------------------------- Captured Err ---------------------------------

</system-err></testcase><testcase classname="tests.bundle.test_bundle" name="test_stake_check_in_bundler" time="0.160"><failure message="AttributeError: 'Error' object has no attribute 'result'">tests/bundle/test_bundle.py:382: in test_stake_check_in_bundler
    response = get_stake_status(paymaster_contract.address, entrypoint_contract.address)
tests/utils.py:165: in get_stake_status
    .result
E   AttributeError: 'Error' object has no attribute 'result'</failure><system-out>--------------------------------- Captured Log ---------------------------------

--------------------------------- Captured Out ---------------------------------

</system-out><system-err>--------------------------------- Captured Err ---------------------------------

</system-err></testcase><testcase classname="tests.bundle.test_codehash" name="test_codehash_changed" time="1.209" /><testcase classname="tests.bundle.test_storage_rules" name="test_rule[[STO-000]unstaked][paymaster][no_storage][ok]" time="0.324" /><testcase classname="tests.bundle.test_storage_rules" name="test_rule[[STO-031]unstaked][paymaster][storage][drop]" time="0.332" /><testcase classname="tests.bundle.test_storage_rules" name="test_rule[[STO-032]unstaked][paymaster][reference_storage][drop]" time="0.460" /><testcase classname="tests.bundle.test_storage_rules" name="test_rule[[STO-032]unstaked][paymaster][reference_storage_struct][drop]" time="0.366" /><testcase classname="tests.bundle.test_storage_rules" name="test_rule[[STO-010]unstaked][paymaster][account_storage][ok]" time="0.345" /><testcase classname="tests.bundle.test_storage_rules" name="test_rule[[STO-021]unstaked][paymaster][account_reference_storage][ok]" time="0.459" /><testcase classname="tests.bundle.test_storage_rules" name="test_rule[[STO-021]unstaked][paymaster][account_reference_storage_struct][ok]" time="0.474" /><testcase classname="tests.bundle.test_storage_rules" name="test_rule[[STO-022]unstaked][paymaster][account_reference_storage_init_code][drop0]" time="0.618" /><testcase classname="tests.bundle.test_storage_rules" name="test_rule[[EREP-050]unstaked][paymaster][context][drop]" time="0.253" /><testcase classname="tests.bundle.test_storage_rules" name="test_rule[[STO-032]unstaked][paymaster][external_storage][drop]" time="0.384" /><testcase classname="tests.bundle.test_storage_rules" name="test_rule[[OP-020]unstaked][paymaster][out_of_gas][drop]" time="0.450" /><testcase classname="tests.bundle.test_storage_rules" name="test_rule[[OP-020]unstaked][paymaster][sstore_out_of_gas][drop]" time="0.377" /><testcase classname="tests.bundle.test_storage_rules" name="test_rule[[STO-000]staked][paymaster][no_storage][ok]" time="0.367" /><testcase classname="tests.bundle.test_storage_rules" name="test_rule[[STO-031]staked][paymaster][storage][ok]" time="0.366" /><testcase classname="tests.bundle.test_storage_rules" name="test_rule[[STO-032]staked][paymaster][reference_storage][ok]" time="0.410" /><testcase classname="tests.bundle.test_storage_rules" name="test_rule[[STO-032]staked][paymaster][reference_storage_struct][ok]" time="0.398" /><testcase classname="tests.bundle.test_storage_rules" name="test_rule[[STO-010]staked][paymaster][account_storage][ok]" time="0.370" /><testcase classname="tests.bundle.test_storage_rules" name="test_rule[[STO-021]staked][paymaster][account_reference_storage][ok]" time="0.380" /><testcase classname="tests.bundle.test_storage_rules" name="test_rule[[STO-021]staked][paymaster][account_reference_storage_struct][ok]" time="0.399" /><testcase classname="tests.bundle.test_storage_rules" name="test_rule[[STO-022]staked][paymaster][account_reference_storage_init_code][ok]" time="0.653" /><testcase classname="tests.bundle.test_storage_rules" name="test_rule[[EREP-050]staked][paymaster][context][ok]" time="0.292" /><testcase classname="tests.bundle.test_storage_rules" name="test_rule[[STO-031]staked][paymaster][external_storage][drop]" time="0.389" /><testcase classname="tests.bundle.test_storage_rules" name="test_rule[[OP-020]staked][paymaster][out_of_gas][drop]" time="0.486" /><testcase classname="tests.bundle.test_storage_rules" name="test_rule[[OP-020]staked][paymaster][sstore_out_of_gas][drop]" time="0.391" /><testcase classname="tests.bundle.test_storage_rules" name="test_rule[[STO-000]unstaked][factory][no_storage][ok]" time="0.479" /><testcase classname="tests.bundle.test_storage_rules" name="test_rule[[STO-000]unstaked][factory][storage][drop]" time="0.487" /><testcase classname="tests.bundle.test_storage_rules" name="test_rule[[STO-000]unstaked][factory][reference_storage][drop]" time="0.506" /><testcase classname="tests.bundle.test_storage_rules" name="test_rule[[STO-032]unstaked][factory][reference_storage_struct][drop]" time="0.537" /><testcase classname="tests.bundle.test_storage_rules" name="test_rule[[STO-010]unstaked][factory][account_storage][ok]" time="0.502" /><testcase classname="tests.bundle.test_storage_rules" name="test_rule[[STO-021]unstaked][factory][account_reference_storage][drop]" time="0.506" /><testcase classname="tests.bundle.test_storage_rules" name="test_rule[[STO-021]unstaked][factory][account_reference_storage_struct][drop]" time="0.525" /><testcase classname="tests.bundle.test_storage_rules" name="test_rule[[STO-000]unstaked][factory][external_storage][drop]" time="0.513" /><testcase classname="tests.bundle.test_storage_rules" name="test_rule[[OP-042]unstaked][factory][EXTCODEx_CALLx_undeployed_sender][ok]" time="0.451" /><testcase classname="tests.bundle.test_storage_rules" name="test_rule[[OP-041]unstaked][factory][EXTCODESIZE_undeployed_contract][drop]" time="0.463" /><testcase classname="tests.bundle.test_storage_rules" name="test_rule[[OP-041]unstaked][factory][EXTCODEHASH_undeployed_contract][drop]" time="0.474" /><testcase classname="tests.bundle.test_storage_rules" name="test_rule[[OP-041]unstaked][factory][EXTCODECOPY_undeployed_contract][drop]" time="0.465" /><testcase classname="tests.bundle.test_storage_rules" name="test_rule[[OP-041]unstaked][factory][CALL_undeployed_contract][drop]" time="0.453" /><testcase classname="tests.bundle.test_storage_rules" name="test_rule[[OP-041]unstaked][factory][CALLCODE_undeployed_contract][drop]" time="0.473" /><testcase classname="tests.bundle.test_storage_rules" name="test_rule[[OP-041]unstaked][factory][DELEGATECALL_undeployed_contract][drop]" time="0.466" /><testcase classname="tests.bundle.test_storage_rules" name="test_rule[[OP-041]unstaked][factory][STATICCALL_undeployed_contract][drop]" time="0.481" /><testcase classname="tests.bundle.test_storage_rules" name="test_rule[[OP-020]unstaked][factory][out_of_gas][drop]" time="0.610" /><testcase classname="tests.bundle.test_storage_rules" name="test_rule[[OP-020]unstaked][factory][sstore_out_of_gas][drop]" time="0.624" /><testcase classname="tests.bundle.test_storage_rules" name="test_rule[[STO-000]staked][factory][no_storage][ok]" time="0.617" /><testcase classname="tests.bundle.test_storage_rules" name="test_rule[[STO-031]staked][factory][storage][ok]" time="0.523" /><testcase classname="tests.bundle.test_storage_rules" name="test_rule[[STO-032]staked][factory][reference_storage][ok]" time="0.537" /><testcase classname="tests.bundle.test_storage_rules" name="test_rule[[STO-032]staked][factory][reference_storage_struct][ok]" time="0.564" /><testcase classname="tests.bundle.test_storage_rules" name="test_rule[[STO-010]staked][factory][account_storage][ok]" time="0.529" /><testcase classname="tests.bundle.test_storage_rules" name="test_rule[[STO-021]staked][factory][account_reference_storage][ok]" time="0.540" /><testcase classname="tests.bundle.test_storage_rules" name="test_rule[[STO-021]staked][factory][account_reference_storage_struct][ok]" time="0.559" /><testcase classname="tests.bundle.test_storage_rules" name="test_rule[[STO-000]staked][factory][external_storage][drop]" time="0.539" /><testcase classname="tests.bundle.test_storage_rules" name="test_rule[[OP-020]staked][factory][out_of_gas][drop]" time="0.654" /><testcase classname="tests.bundle.test_storage_rules" name="test_rule[[OP-020]staked][factory][sstore_out_of_gas][drop]" time="0.549" /><testcase classname="tests.bundle.test_storage_rules" name="test_rule[[STO-000]unstaked][account][no_storage][ok]" time="0.332" /><testcase classname="tests.bundle.test_storage_rules" name="test_rule[[STO-010]unstaked][account][account_storage][ok]" time="0.294" /><testcase classname="tests.bundle.test_storage_rules" name="test_rule[[STO-021]unstaked][account][account_reference_storage][ok]" time="0.345" /><testcase classname="tests.bundle.test_storage_rules" name="test_rule[[STO-022]unstaked][account][account_reference_storage_init_code][drop]" time="0.584" /><testcase classname="tests.bundle.test_storage_rules" name="test_rule[[STO-022]unstaked][account][account_reference_storage_init_code][ok]" time="0.650" /><testcase classname="tests.bundle.test_storage_rules" name="test_rule[[STO-022]unstaked][paymaster][account_reference_storage_init_code][drop1]" time="0.554" /><testcase classname="tests.bundle.test_storage_rules" name="test_rule[[STO-021]unstaked][account][account_reference_storage_struct][ok]" time="0.320" /><testcase classname="tests.bundle.test_storage_rules" name="test_rule[[STO-000]unstaked][account][external_storage][drop]" time="0.312" /><testcase classname="tests.bundle.test_storage_rules" name="test_rule[[OP-020]unstaked][account][out_of_gas][drop]" time="0.402" /><testcase classname="tests.bundle.test_storage_rules" name="test_rule[[OP-020]unstaked][account][sstore_out_of_gas][drop]" time="0.314" /><testcase classname="tests.bundle.test_storage_rules" name="test_rule[[STO-000]staked][account][no_storage][ok]" time="0.305" /><testcase classname="tests.bundle.test_storage_rules" name="test_rule[[STO-010]staked][account][account_storage][ok]" time="0.328" /><testcase classname="tests.bundle.test_storage_rules" name="test_rule[[STO-021]staked][account][account_reference_storage][ok]" time="0.344" /><testcase classname="tests.bundle.test_storage_rules" name="test_rule[[STO-021]staked][account][account_reference_storage_struct][ok]" time="0.372" /><testcase classname="tests.bundle.test_storage_rules" name="test_rule[[OP-020]staked][account][out_of_gas][drop]" time="0.428" /><testcase classname="tests.bundle.test_storage_rules" name="test_rule[[OP-020]staked][account][sstore_out_of_gas][drop]" time="0.348" /><testcase classname="tests.bundle.test_storage_rules" name="test_rule[[STO-000]staked][account][external_storage][drop]" time="0.348" /><testcase classname="tests.bundle.test_storage_rules" name="test_rule[[OP-011]unstaked][account][entryPoint_call_balanceOf][drop]" time="0.323" /><testcase classname="tests.bundle.test_storage_rules" name="test_rule[[OP-061]unstaked][account][eth_value_transfer_forbidden][drop]" time="0.321" /><testcase classname="tests.bundle.test_storage_rules" name="test_rule[[OP-053]unstaked][account][eth_value_transfer_entryPoint][ok]" time="0.335" /><testcase classname="tests.bundle.test_storage_rules" name="test_rule[[OP-052]unstaked][account][eth_value_transfer_entryPoint_depositTo][ok]" time="0.343" /><testcase classname="tests.bundle.test_storage_rules" name="test_rule[[OP-041]unstaked][account][EXTCODESIZE_undeployed_contract][drop]" time="0.259" /><testcase classname="tests.bundle.test_storage_rules" name="test_rule[[OP-041]unstaked][account][EXTCODEHASH_undeployed_contract][drop]" time="0.260" /><testcase classname="tests.bundle.test_storage_rules" name="test_rule[[OP-041]unstaked][account][EXTCODECOPY_undeployed_contract][drop]" time="0.258" /><testcase classname="tests.bundle.test_storage_rules" name="test_rule[[OP-054]unstaked][account][EXTCODESIZE_entrypoint][drop]" time="0.283" /><testcase classname="tests.bundle.test_storage_rules" name="test_rule[[OP-054]unstaked][account][EXTCODEHASH_entrypoint][drop]" time="0.284" /><testcase classname="tests.bundle.test_storage_rules" name="test_rule[[OP-054]unstaked][account][EXTCODECOPY_entrypoint][drop]" time="0.289" /><testcase classname="tests.bundle.test_storage_rules" name="test_rule[[OP-041]unstaked][account][CALL_undeployed_contract][drop]" time="0.254" /><testcase classname="tests.bundle.test_storage_rules" name="test_rule[[OP-041]unstaked][account][CALLCODE_undeployed_contract][drop]" time="0.252" /><testcase classname="tests.bundle.test_storage_rules" name="test_rule[[OP-041]unstaked][account][DELEGATECALL_undeployed_contract][drop]" time="0.270" /><testcase classname="tests.bundle.test_storage_rules" name="test_rule[[OP-041]unstaked][account][STATICCALL_undeployed_contract][drop]" time="0.361" /><testcase classname="tests.bundle.test_storage_rules" name="test_rule[[OP-062]unstaked][account][CALL_undeployed_contract_allowed_precompile][ok]" time="0.303" /><testcase classname="tests.opbanning.test_op_banning" name="test_account_banned_opcode[GAS]" time="0.199" /><testcase classname="tests.opbanning.test_op_banning" name="test_account_banned_opcode[NUMBER]" time="0.200" /><testcase classname="tests.opbanning.test_op_banning" name="test_account_banned_opcode[TIMESTAMP]" time="0.224" /><testcase classname="tests.opbanning.test_op_banning" name="test_account_banned_opcode[COINBASE]" time="0.202" /><testcase classname="tests.opbanning.test_op_banning" name="test_account_banned_opcode[DIFFICULTY]" time="0.208" /><testcase classname="tests.opbanning.test_op_banning" name="test_account_banned_opcode[BASEFEE]" time="0.208" /><testcase classname="tests.opbanning.test_op_banning" name="test_account_banned_opcode[GASLIMIT]" time="0.208" /><testcase classname="tests.opbanning.test_op_banning" name="test_account_banned_opcode[GASPRICE]" time="0.210" /><testcase classname="tests.opbanning.test_op_banning" name="test_account_banned_opcode[SELFBALANCE]" time="0.214" /><testcase classname="tests.opbanning.test_op_banning" name="test_account_banned_opcode[BALANCE]" time="0.215" /><testcase classname="tests.opbanning.test_op_banning" name="test_account_banned_opcode[ORIGIN]" time="0.320" /><testcase classname="tests.opbanning.test_op_banning" name="test_account_banned_opcode[BLOCKHASH]" time="0.224" /><testcase classname="tests.opbanning.test_op_banning" name="test_account_banned_opcode[CREATE]" time="0.234" /><testcase classname="tests.opbanning.test_op_banning" name="test_account_banned_opcode[CREATE2]" time="0.232" /><testcase classname="tests.opbanning.test_op_banning" name="test_account_banned_opcode[SELFDESTRUCT]" time="0.231" /><testcase classname="tests.opbanning.test_op_banning" name="test_account_allowed_opcode_sequence[GAS CALL]" time="0.268" /><testcase classname="tests.opbanning.test_op_banning" name="test_account_allowed_opcode_sequence[GAS DELEGATECALL]" time="0.265" /><testcase classname="tests.opbanning.test_op_banning" name="test_paymaster_banned_opcode[GAS]" time="0.264" /><testcase classname="tests.opbanning.test_op_banning" name="test_paymaster_banned_opcode[NUMBER]" time="0.264" /><testcase classname="tests.opbanning.test_op_banning" name="test_paymaster_banned_opcode[TIMESTAMP]" time="0.300" /><testcase classname="tests.opbanning.test_op_banning" name="test_paymaster_banned_opcode[COINBASE]" time="0.267" /><testcase classname="tests.opbanning.test_op_banning" name="test_paymaster_banned_opcode[DIFFICULTY]" time="0.276" /><testcase classname="tests.opbanning.test_op_banning" name="test_paymaster_banned_opcode[BASEFEE]" time="0.269" /><testcase classname="tests.opbanning.test_op_banning" name="test_paymaster_banned_opcode[GASLIMIT]" time="0.277" /><testcase classname="tests.opbanning.test_op_banning" name="test_paymaster_banned_opcode[GASPRICE]" time="0.376" /><testcase classname="tests.opbanning.test_op_banning" name="test_paymaster_banned_opcode[SELFBALANCE]" time="0.274" /><testcase classname="tests.opbanning.test_op_banning" name="test_paymaster_banned_opcode[BALANCE]" time="0.292" /><testcase classname="tests.opbanning.test_op_banning" name="test_paymaster_banned_opcode[ORIGIN]" time="0.397" /><testcase classname="tests.opbanning.test_op_banning" name="test_paymaster_banned_opcode[BLOCKHASH]" time="0.288" /><testcase classname="tests.opbanning.test_op_banning" name="test_paymaster_banned_opcode[CREATE]" time="0.301" /><testcase classname="tests.opbanning.test_op_banning" name="test_paymaster_banned_opcode[CREATE2]" time="0.296" /><testcase classname="tests.opbanning.test_op_banning" name="test_paymaster_banned_opcode[SELFDESTRUCT]" time="0.302" /><testcase classname="tests.opbanning.test_op_banning" name="test_factory_banned_opcode[GAS]" time="0.413" /><testcase classname="tests.opbanning.test_op_banning" name="test_factory_banned_opcode[NUMBER]" time="0.420" /><testcase classname="tests.opbanning.test_op_banning" name="test_factory_banned_opcode[TIMESTAMP]" time="0.424" /><testcase classname="tests.opbanning.test_op_banning" name="test_factory_banned_opcode[COINBASE]" time="0.429" /><testcase classname="tests.opbanning.test_op_banning" name="test_factory_banned_opcode[DIFFICULTY]" time="0.431" /><testcase classname="tests.opbanning.test_op_banning" name="test_factory_banned_opcode[BASEFEE]" time="0.438" /><testcase classname="tests.opbanning.test_op_banning" name="test_factory_banned_opcode[GASLIMIT]" time="0.434" /><testcase classname="tests.opbanning.test_op_banning" name="test_factory_banned_opcode[GASPRICE]" time="0.432" /><testcase classname="tests.opbanning.test_op_banning" name="test_factory_banned_opcode[SELFBALANCE]" time="0.435" /><testcase classname="tests.opbanning.test_op_banning" name="test_factory_banned_opcode[BALANCE]" time="0.453" /><testcase classname="tests.opbanning.test_op_banning" name="test_factory_banned_opcode[ORIGIN]" time="0.564" /><testcase classname="tests.opbanning.test_op_banning" name="test_factory_banned_opcode[BLOCKHASH]" time="0.439" /><testcase classname="tests.opbanning.test_op_banning" name="test_factory_banned_opcode[CREATE]" time="0.457" /><testcase classname="tests.opbanning.test_op_banning" name="test_factory_banned_opcode[CREATE2]" time="0.461" /><testcase classname="tests.opbanning.test_op_banning" name="test_factory_banned_opcode[SELFDESTRUCT]" time="0.458" /><testcase classname="tests.reputation.test_reputation" name="test_staked_entity_reputation_threshold[with_factory]" time="75.267"><failure message="TypeError: int() can't convert non-string with explicit base">tests/reputation/test_reputation.py:127: in test_staked_entity_reputation_threshold
    assert_reputation_status(
tests/reputation/test_reputation.py:49: in assert_reputation_status
    assert int(reputation.get("status", "-0x1"), 16) == status, (
E   TypeError: int() can't convert non-string with explicit base</failure><system-out>--------------------------------- Captured Log ---------------------------------

--------------------------------- Captured Out ---------------------------------

</system-out><system-err>--------------------------------- Captured Err ---------------------------------

</system-err></testcase><testcase classname="tests.reputation.test_reputation" name="test_staked_entity_reputation_threshold[without_factory]" time="20.954"><failure message="TypeError: int() can't convert non-string with explicit base">tests/reputation/test_reputation.py:134: in test_staked_entity_reputation_threshold
    assert_reputation_status(
tests/reputation/test_reputation.py:49: in assert_reputation_status
    assert int(reputation.get("status", "-0x1"), 16) == status, (
E   TypeError: int() can't convert non-string with explicit base</failure><system-out>--------------------------------- Captured Log ---------------------------------

--------------------------------- Captured Out ---------------------------------

</system-out><system-err>--------------------------------- Captured Err ---------------------------------

</system-err></testcase><testcase classname="tests.rpc.test_eth_chainId" name="test_eth_chainId[]" time="0.009" /><testcase classname="tests.rpc.test_eth_estimateUserOperationGas" name="test_eth_estimateUserOperationGas[]" time="0.156" /><testcase classname="tests.rpc.test_eth_estimateUserOperationGas" name="test_eth_estimateUserOperationGas_execution_revert" time="0.159" /><testcase classname="tests.rpc.test_eth_estimateUserOperationGas" name="test_eth_estimateUserOperationGas_simulation_revert" time="0.030" /><testcase classname="tests.rpc.test_eth_getUserOperationByHash" name="test_eth_getUserOperationByHash[]" time="0.636" /><testcase classname="tests.rpc.test_eth_getUserOperationByHash" name="test_eth_getUserOperationByHash_error" time="0.003" /><testcase classname="tests.rpc.test_eth_getUserOperationReceipt" name="test_eth_getUserOperationReceipt[]" time="0.155"><error message="failed on setup with &quot;requests.exceptions.ConnectionError: ('Connection aborted.', RemoteDisconnected('Remote end closed connection without response'))&quot;">.venv/lib/python3.10/site-packages/urllib3/connectionpool.py:703: in urlopen
    httplib_response = self._make_request(
.venv/lib/python3.10/site-packages/urllib3/connectionpool.py:449: in _make_request
    six.raise_from(e, None)
&lt;string&gt;:3: in raise_from
    ???
.venv/lib/python3.10/site-packages/urllib3/connectionpool.py:444: in _make_request
    httplib_response = conn.getresponse()
/usr/lib/python3.10/http/client.py:1375: in getresponse
    response.begin()
/usr/lib/python3.10/http/client.py:318: in begin
    version, status, reason = self._read_status()
/usr/lib/python3.10/http/client.py:287: in _read_status
    raise RemoteDisconnected("Remote end closed connection without"
E   http.client.RemoteDisconnected: Remote end closed connection without response

During handling of the above exception, another exception occurred:
.venv/lib/python3.10/site-packages/requests/adapters.py:489: in send
    resp = conn.urlopen(
.venv/lib/python3.10/site-packages/urllib3/connectionpool.py:787: in urlopen
    retries = retries.increment(
.venv/lib/python3.10/site-packages/urllib3/util/retry.py:550: in increment
    raise six.reraise(type(error), error, _stacktrace)
.venv/lib/python3.10/site-packages/urllib3/packages/six.py:769: in reraise
    raise value.with_traceback(tb)
.venv/lib/python3.10/site-packages/urllib3/connectionpool.py:703: in urlopen
    httplib_response = self._make_request(
.venv/lib/python3.10/site-packages/urllib3/connectionpool.py:449: in _make_request
    six.raise_from(e, None)
&lt;string&gt;:3: in raise_from
    ???
.venv/lib/python3.10/site-packages/urllib3/connectionpool.py:444: in _make_request
    httplib_response = conn.getresponse()
/usr/lib/python3.10/http/client.py:1375: in getresponse
    response.begin()
/usr/lib/python3.10/http/client.py:318: in begin
    version, status, reason = self._read_status()
/usr/lib/python3.10/http/client.py:287: in _read_status
    raise RemoteDisconnected("Remote end closed connection without"
E   urllib3.exceptions.ProtocolError: ('Connection aborted.', RemoteDisconnected('Remote end closed connection without response'))

During handling of the above exception, another exception occurred:
tests/conftest.py:106: in execute_user_operation
    userop.send()
tests/types.py:52: in send
    ).send(url)
tests/types.py:69: in send
    requests.post(url, json=asdict(self), timeout=10).json()
.venv/lib/python3.10/site-packages/requests/api.py:115: in post
    return request("post", url, data=data, json=json, **kwargs)
.venv/lib/python3.10/site-packages/requests/api.py:59: in request
    return session.request(method=method, url=url, **kwargs)
.venv/lib/python3.10/site-packages/requests/sessions.py:587: in request
    resp = self.send(prep, **send_kwargs)
.venv/lib/python3.10/site-packages/requests/sessions.py:701: in send
    r = adapter.send(request, **kwargs)
.venv/lib/python3.10/site-packages/requests/adapters.py:547: in send
    raise ConnectionError(err, request=request)
E   requests.exceptions.ConnectionError: ('Connection aborted.', RemoteDisconnected('Remote end closed connection without response'))</error></testcase><testcase classname="tests.rpc.test_eth_getUserOperationReceipt" name="test_eth_getUserOperationReceipt_error" time="0.002"><failure message="requests.exceptions.ConnectionError: HTTPConnectionPool(host='localhost', port=3000): Max retries exceeded with url: /rpc (Caused by NewConnectionError('&lt;urllib3.connection.HTTPConnection object at 0x7f13f94d9a20&gt;: Failed to establish a new connection: [Errno 111] Connection refused'))">.venv/lib/python3.10/site-packages/urllib3/connection.py:174: in _new_conn
    conn = connection.create_connection(
.venv/lib/python3.10/site-packages/urllib3/util/connection.py:95: in create_connection
    raise err
.venv/lib/python3.10/site-packages/urllib3/util/connection.py:85: in create_connection
    sock.connect(sa)
E   ConnectionRefusedError: [Errno 111] Connection refused

During handling of the above exception, another exception occurred:
.venv/lib/python3.10/site-packages/urllib3/connectionpool.py:703: in urlopen
    httplib_response = self._make_request(
.venv/lib/python3.10/site-packages/urllib3/connectionpool.py:398: in _make_request
    conn.request(method, url, **httplib_request_kw)
.venv/lib/python3.10/site-packages/urllib3/connection.py:239: in request
    super(HTTPConnection, self).request(method, url, body=body, headers=headers)
/usr/lib/python3.10/http/client.py:1283: in request
    self._send_request(method, url, body, headers, encode_chunked)
/usr/lib/python3.10/http/client.py:1329: in _send_request
    self.endheaders(body, encode_chunked=encode_chunked)
/usr/lib/python3.10/http/client.py:1278: in endheaders
    self._send_output(message_body, encode_chunked=encode_chunked)
/usr/lib/python3.10/http/client.py:1038: in _send_output
    self.send(msg)
/usr/lib/python3.10/http/client.py:976: in send
    self.connect()
.venv/lib/python3.10/site-packages/urllib3/connection.py:205: in connect
    conn = self._new_conn()
.venv/lib/python3.10/site-packages/urllib3/connection.py:186: in _new_conn
    raise NewConnectionError(
E   urllib3.exceptions.NewConnectionError: &lt;urllib3.connection.HTTPConnection object at 0x7f13f94d9a20&gt;: Failed to establish a new connection: [Errno 111] Connection refused

During handling of the above exception, another exception occurred:
.venv/lib/python3.10/site-packages/requests/adapters.py:489: in send
    resp = conn.urlopen(
.venv/lib/python3.10/site-packages/urllib3/connectionpool.py:787: in urlopen
    retries = retries.increment(
.venv/lib/python3.10/site-packages/urllib3/util/retry.py:592: in increment
    raise MaxRetryError(_pool, url, error or ResponseError(cause))
E   urllib3.exceptions.MaxRetryError: HTTPConnectionPool(host='localhost', port=3000): Max retries exceeded with url: /rpc (Caused by NewConnectionError('&lt;urllib3.connection.HTTPConnection object at 0x7f13f94d9a20&gt;: Failed to establish a new connection: [Errno 111] Connection refused'))

During handling of the above exception, another exception occurred:
tests/rpc/test_eth_getUserOperationReceipt.py:25: in test_eth_getUserOperationReceipt_error
    response = RPCRequest(method="eth_getUserOperationReceipt", params=[""]).send()
tests/types.py:69: in send
    requests.post(url, json=asdict(self), timeout=10).json()
.venv/lib/python3.10/site-packages/requests/api.py:115: in post
    return request("post", url, data=data, json=json, **kwargs)
.venv/lib/python3.10/site-packages/requests/api.py:59: in request
    return session.request(method=method, url=url, **kwargs)
.venv/lib/python3.10/site-packages/requests/sessions.py:587: in request
    resp = self.send(prep, **send_kwargs)
.venv/lib/python3.10/site-packages/requests/sessions.py:701: in send
    r = adapter.send(request, **kwargs)
.venv/lib/python3.10/site-packages/requests/adapters.py:565: in send
    raise ConnectionError(e, request=request)
E   requests.exceptions.ConnectionError: HTTPConnectionPool(host='localhost', port=3000): Max retries exceeded with url: /rpc (Caused by NewConnectionError('&lt;urllib3.connection.HTTPConnection object at 0x7f13f94d9a20&gt;: Failed to establish a new connection: [Errno 111] Connection refused'))</failure><system-out>--------------------------------- Captured Log ---------------------------------

--------------------------------- Captured Out ---------------------------------

</system-out><system-err>--------------------------------- Captured Err ---------------------------------

</system-err></testcase><testcase classname="tests.rpc.test_eth_sendUserOperation" name="test_eth_sendUserOperation[]" time="0.029"><failure message="requests.exceptions.ConnectionError: HTTPConnectionPool(host='localhost', port=3000): Max retries exceeded with url: /rpc (Caused by NewConnectionError('&lt;urllib3.connection.HTTPConnection object at 0x7f13f95035b0&gt;: Failed to establish a new connection: [Errno 111] Connection refused'))">.venv/lib/python3.10/site-packages/urllib3/connection.py:174: in _new_conn
    conn = connection.create_connection(
.venv/lib/python3.10/site-packages/urllib3/util/connection.py:95: in create_connection
    raise err
.venv/lib/python3.10/site-packages/urllib3/util/connection.py:85: in create_connection
    sock.connect(sa)
E   ConnectionRefusedError: [Errno 111] Connection refused

During handling of the above exception, another exception occurred:
.venv/lib/python3.10/site-packages/urllib3/connectionpool.py:703: in urlopen
    httplib_response = self._make_request(
.venv/lib/python3.10/site-packages/urllib3/connectionpool.py:398: in _make_request
    conn.request(method, url, **httplib_request_kw)
.venv/lib/python3.10/site-packages/urllib3/connection.py:239: in request
    super(HTTPConnection, self).request(method, url, body=body, headers=headers)
/usr/lib/python3.10/http/client.py:1283: in request
    self._send_request(method, url, body, headers, encode_chunked)
/usr/lib/python3.10/http/client.py:1329: in _send_request
    self.endheaders(body, encode_chunked=encode_chunked)
/usr/lib/python3.10/http/client.py:1278: in endheaders
    self._send_output(message_body, encode_chunked=encode_chunked)
/usr/lib/python3.10/http/client.py:1038: in _send_output
    self.send(msg)
/usr/lib/python3.10/http/client.py:976: in send
    self.connect()
.venv/lib/python3.10/site-packages/urllib3/connection.py:205: in connect
    conn = self._new_conn()
.venv/lib/python3.10/site-packages/urllib3/connection.py:186: in _new_conn
    raise NewConnectionError(
E   urllib3.exceptions.NewConnectionError: &lt;urllib3.connection.HTTPConnection object at 0x7f13f95035b0&gt;: Failed to establish a new connection: [Errno 111] Connection refused

During handling of the above exception, another exception occurred:
.venv/lib/python3.10/site-packages/requests/adapters.py:489: in send
    resp = conn.urlopen(
.venv/lib/python3.10/site-packages/urllib3/connectionpool.py:787: in urlopen
    retries = retries.increment(
.venv/lib/python3.10/site-packages/urllib3/util/retry.py:592: in increment
    raise MaxRetryError(_pool, url, error or ResponseError(cause))
E   urllib3.exceptions.MaxRetryError: HTTPConnectionPool(host='localhost', port=3000): Max retries exceeded with url: /rpc (Caused by NewConnectionError('&lt;urllib3.connection.HTTPConnection object at 0x7f13f95035b0&gt;: Failed to establish a new connection: [Errno 111] Connection refused'))

During handling of the above exception, another exception occurred:
tests/rpc/test_eth_sendUserOperation.py:16: in test_eth_sendUserOperation
    response = userop.send()
tests/types.py:52: in send
    ).send(url)
tests/types.py:69: in send
    requests.post(url, json=asdict(self), timeout=10).json()
.venv/lib/python3.10/site-packages/requests/api.py:115: in post
    return request("post", url, data=data, json=json, **kwargs)
.venv/lib/python3.10/site-packages/requests/api.py:59: in request
    return session.request(method=method, url=url, **kwargs)
.venv/lib/python3.10/site-packages/requests/sessions.py:587: in request
    resp = self.send(prep, **send_kwargs)
.venv/lib/python3.10/site-packages/requests/sessions.py:701: in send
    r = adapter.send(request, **kwargs)
.venv/lib/python3.10/site-packages/requests/adapters.py:565: in send
    raise ConnectionError(e, request=request)
E   requests.exceptions.ConnectionError: HTTPConnectionPool(host='localhost', port=3000): Max retries exceeded with url: /rpc (Caused by NewConnectionError('&lt;urllib3.connection.HTTPConnection object at 0x7f13f95035b0&gt;: Failed to establish a new connection: [Errno 111] Connection refused'))</failure><system-out>--------------------------------- Captured Log ---------------------------------

--------------------------------- Captured Out ---------------------------------

</system-out><system-err>--------------------------------- Captured Err ---------------------------------

</system-err></testcase><testcase classname="tests.rpc.test_eth_sendUserOperation" name="test_eth_sendUserOperation_revert" time="0.029"><failure message="requests.exceptions.ConnectionError: HTTPConnectionPool(host='localhost', port=3000): Max retries exceeded with url: /rpc (Caused by NewConnectionError('&lt;urllib3.connection.HTTPConnection object at 0x7f13f9168a00&gt;: Failed to establish a new connection: [Errno 111] Connection refused'))">.venv/lib/python3.10/site-packages/urllib3/connection.py:174: in _new_conn
    conn = connection.create_connection(
.venv/lib/python3.10/site-packages/urllib3/util/connection.py:95: in create_connection
    raise err
.venv/lib/python3.10/site-packages/urllib3/util/connection.py:85: in create_connection
    sock.connect(sa)
E   ConnectionRefusedError: [Errno 111] Connection refused

During handling of the above exception, another exception occurred:
.venv/lib/python3.10/site-packages/urllib3/connectionpool.py:703: in urlopen
    httplib_response = self._make_request(
.venv/lib/python3.10/site-packages/urllib3/connectionpool.py:398: in _make_request
    conn.request(method, url, **httplib_request_kw)
.venv/lib/python3.10/site-packages/urllib3/connection.py:239: in request
    super(HTTPConnection, self).request(method, url, body=body, headers=headers)
/usr/lib/python3.10/http/client.py:1283: in request
    self._send_request(method, url, body, headers, encode_chunked)
/usr/lib/python3.10/http/client.py:1329: in _send_request
    self.endheaders(body, encode_chunked=encode_chunked)
/usr/lib/python3.10/http/client.py:1278: in endheaders
    self._send_output(message_body, encode_chunked=encode_chunked)
/usr/lib/python3.10/http/client.py:1038: in _send_output
    self.send(msg)
/usr/lib/python3.10/http/client.py:976: in send
    self.connect()
.venv/lib/python3.10/site-packages/urllib3/connection.py:205: in connect
    conn = self._new_conn()
.venv/lib/python3.10/site-packages/urllib3/connection.py:186: in _new_conn
    raise NewConnectionError(
E   urllib3.exceptions.NewConnectionError: &lt;urllib3.connection.HTTPConnection object at 0x7f13f9168a00&gt;: Failed to establish a new connection: [Errno 111] Connection refused

During handling of the above exception, another exception occurred:
.venv/lib/python3.10/site-packages/requests/adapters.py:489: in send
    resp = conn.urlopen(
.venv/lib/python3.10/site-packages/urllib3/connectionpool.py:787: in urlopen
    retries = retries.increment(
.venv/lib/python3.10/site-packages/urllib3/util/retry.py:592: in increment
    raise MaxRetryError(_pool, url, error or ResponseError(cause))
E   urllib3.exceptions.MaxRetryError: HTTPConnectionPool(host='localhost', port=3000): Max retries exceeded with url: /rpc (Caused by NewConnectionError('&lt;urllib3.connection.HTTPConnection object at 0x7f13f9168a00&gt;: Failed to establish a new connection: [Errno 111] Connection refused'))

During handling of the above exception, another exception occurred:
tests/rpc/test_eth_sendUserOperation.py:28: in test_eth_sendUserOperation_revert
    response = bad_sig_userop.send()
tests/types.py:52: in send
    ).send(url)
tests/types.py:69: in send
    requests.post(url, json=asdict(self), timeout=10).json()
.venv/lib/python3.10/site-packages/requests/api.py:115: in post
    return request("post", url, data=data, json=json, **kwargs)
.venv/lib/python3.10/site-packages/requests/api.py:59: in request
    return session.request(method=method, url=url, **kwargs)
.venv/lib/python3.10/site-packages/requests/sessions.py:587: in request
    resp = self.send(prep, **send_kwargs)
.venv/lib/python3.10/site-packages/requests/sessions.py:701: in send
    r = adapter.send(request, **kwargs)
.venv/lib/python3.10/site-packages/requests/adapters.py:565: in send
    raise ConnectionError(e, request=request)
E   requests.exceptions.ConnectionError: HTTPConnectionPool(host='localhost', port=3000): Max retries exceeded with url: /rpc (Caused by NewConnectionError('&lt;urllib3.connection.HTTPConnection object at 0x7f13f9168a00&gt;: Failed to establish a new connection: [Errno 111] Connection refused'))</failure><system-out>--------------------------------- Captured Log ---------------------------------

--------------------------------- Captured Out ---------------------------------

</system-out><system-err>--------------------------------- Captured Err ---------------------------------

</system-err></testcase><testcase classname="tests.rpc.test_eth_sendUserOperation" name="test_eth_sendUserOperation_invalid_signature" time="0.024"><failure message="requests.exceptions.ConnectionError: HTTPConnectionPool(host='localhost', port=3000): Max retries exceeded with url: /rpc (Caused by NewConnectionError('&lt;urllib3.connection.HTTPConnection object at 0x7f13f9328310&gt;: Failed to establish a new connection: [Errno 111] Connection refused'))">.venv/lib/python3.10/site-packages/urllib3/connection.py:174: in _new_conn
    conn = connection.create_connection(
.venv/lib/python3.10/site-packages/urllib3/util/connection.py:95: in create_connection
    raise err
.venv/lib/python3.10/site-packages/urllib3/util/connection.py:85: in create_connection
    sock.connect(sa)
E   ConnectionRefusedError: [Errno 111] Connection refused

During handling of the above exception, another exception occurred:
.venv/lib/python3.10/site-packages/urllib3/connectionpool.py:703: in urlopen
    httplib_response = self._make_request(
.venv/lib/python3.10/site-packages/urllib3/connectionpool.py:398: in _make_request
    conn.request(method, url, **httplib_request_kw)
.venv/lib/python3.10/site-packages/urllib3/connection.py:239: in request
    super(HTTPConnection, self).request(method, url, body=body, headers=headers)
/usr/lib/python3.10/http/client.py:1283: in request
    self._send_request(method, url, body, headers, encode_chunked)
/usr/lib/python3.10/http/client.py:1329: in _send_request
    self.endheaders(body, encode_chunked=encode_chunked)
/usr/lib/python3.10/http/client.py:1278: in endheaders
    self._send_output(message_body, encode_chunked=encode_chunked)
/usr/lib/python3.10/http/client.py:1038: in _send_output
    self.send(msg)
/usr/lib/python3.10/http/client.py:976: in send
    self.connect()
.venv/lib/python3.10/site-packages/urllib3/connection.py:205: in connect
    conn = self._new_conn()
.venv/lib/python3.10/site-packages/urllib3/connection.py:186: in _new_conn
    raise NewConnectionError(
E   urllib3.exceptions.NewConnectionError: &lt;urllib3.connection.HTTPConnection object at 0x7f13f9328310&gt;: Failed to establish a new connection: [Errno 111] Connection refused

During handling of the above exception, another exception occurred:
.venv/lib/python3.10/site-packages/requests/adapters.py:489: in send
    resp = conn.urlopen(
.venv/lib/python3.10/site-packages/urllib3/connectionpool.py:787: in urlopen
    retries = retries.increment(
.venv/lib/python3.10/site-packages/urllib3/util/retry.py:592: in increment
    raise MaxRetryError(_pool, url, error or ResponseError(cause))
E   urllib3.exceptions.MaxRetryError: HTTPConnectionPool(host='localhost', port=3000): Max retries exceeded with url: /rpc (Caused by NewConnectionError('&lt;urllib3.connection.HTTPConnection object at 0x7f13f9328310&gt;: Failed to establish a new connection: [Errno 111] Connection refused'))

During handling of the above exception, another exception occurred:
tests/rpc/test_eth_sendUserOperation.py:39: in test_eth_sendUserOperation_invalid_signature
    invalid_sig_userop.send(),
tests/types.py:52: in send
    ).send(url)
tests/types.py:69: in send
    requests.post(url, json=asdict(self), timeout=10).json()
.venv/lib/python3.10/site-packages/requests/api.py:115: in post
    return request("post", url, data=data, json=json, **kwargs)
.venv/lib/python3.10/site-packages/requests/api.py:59: in request
    return session.request(method=method, url=url, **kwargs)
.venv/lib/python3.10/site-packages/requests/sessions.py:587: in request
    resp = self.send(prep, **send_kwargs)
.venv/lib/python3.10/site-packages/requests/sessions.py:701: in send
    r = adapter.send(request, **kwargs)
.venv/lib/python3.10/site-packages/requests/adapters.py:565: in send
    raise ConnectionError(e, request=request)
E   requests.exceptions.ConnectionError: HTTPConnectionPool(host='localhost', port=3000): Max retries exceeded with url: /rpc (Caused by NewConnectionError('&lt;urllib3.connection.HTTPConnection object at 0x7f13f9328310&gt;: Failed to establish a new connection: [Errno 111] Connection refused'))</failure><system-out>--------------------------------- Captured Log ---------------------------------

--------------------------------- Captured Out ---------------------------------

</system-out><system-err>--------------------------------- Captured Err ---------------------------------

</system-err></testcase><testcase classname="tests.rpc.test_eth_supportedEntryPoints" name="test_eth_supportedEntryPoints[]" time="0.012"><failure message="requests.exceptions.ConnectionError: HTTPConnectionPool(host='localhost', port=3000): Max retries exceeded with url: /rpc (Caused by NewConnectionError('&lt;urllib3.connection.HTTPConnection object at 0x7f13f9205570&gt;: Failed to establish a new connection: [Errno 111] Connection refused'))">.venv/lib/python3.10/site-packages/urllib3/connection.py:174: in _new_conn
    conn = connection.create_connection(
.venv/lib/python3.10/site-packages/urllib3/util/connection.py:95: in create_connection
    raise err
.venv/lib/python3.10/site-packages/urllib3/util/connection.py:85: in create_connection
    sock.connect(sa)
E   ConnectionRefusedError: [Errno 111] Connection refused

During handling of the above exception, another exception occurred:
.venv/lib/python3.10/site-packages/urllib3/connectionpool.py:703: in urlopen
    httplib_response = self._make_request(
.venv/lib/python3.10/site-packages/urllib3/connectionpool.py:398: in _make_request
    conn.request(method, url, **httplib_request_kw)
.venv/lib/python3.10/site-packages/urllib3/connection.py:239: in request
    super(HTTPConnection, self).request(method, url, body=body, headers=headers)
/usr/lib/python3.10/http/client.py:1283: in request
    self._send_request(method, url, body, headers, encode_chunked)
/usr/lib/python3.10/http/client.py:1329: in _send_request
    self.endheaders(body, encode_chunked=encode_chunked)
/usr/lib/python3.10/http/client.py:1278: in endheaders
    self._send_output(message_body, encode_chunked=encode_chunked)
/usr/lib/python3.10/http/client.py:1038: in _send_output
    self.send(msg)
/usr/lib/python3.10/http/client.py:976: in send
    self.connect()
.venv/lib/python3.10/site-packages/urllib3/connection.py:205: in connect
    conn = self._new_conn()
.venv/lib/python3.10/site-packages/urllib3/connection.py:186: in _new_conn
    raise NewConnectionError(
E   urllib3.exceptions.NewConnectionError: &lt;urllib3.connection.HTTPConnection object at 0x7f13f9205570&gt;: Failed to establish a new connection: [Errno 111] Connection refused

During handling of the above exception, another exception occurred:
.venv/lib/python3.10/site-packages/requests/adapters.py:489: in send
    resp = conn.urlopen(
.venv/lib/python3.10/site-packages/urllib3/connectionpool.py:787: in urlopen
    retries = retries.increment(
.venv/lib/python3.10/site-packages/urllib3/util/retry.py:592: in increment
    raise MaxRetryError(_pool, url, error or ResponseError(cause))
E   urllib3.exceptions.MaxRetryError: HTTPConnectionPool(host='localhost', port=3000): Max retries exceeded with url: /rpc (Caused by NewConnectionError('&lt;urllib3.connection.HTTPConnection object at 0x7f13f9205570&gt;: Failed to establish a new connection: [Errno 111] Connection refused'))

During handling of the above exception, another exception occurred:
tests/rpc/test_eth_supportedEntryPoints.py:8: in test_eth_supportedEntryPoints
    response = RPCRequest(method="eth_supportedEntryPoints").send(CommandLineArgs.url)
tests/types.py:69: in send
    requests.post(url, json=asdict(self), timeout=10).json()
.venv/lib/python3.10/site-packages/requests/api.py:115: in post
    return request("post", url, data=data, json=json, **kwargs)
.venv/lib/python3.10/site-packages/requests/api.py:59: in request
    return session.request(method=method, url=url, **kwargs)
.venv/lib/python3.10/site-packages/requests/sessions.py:587: in request
    resp = self.send(prep, **send_kwargs)
.venv/lib/python3.10/site-packages/requests/sessions.py:701: in send
    r = adapter.send(request, **kwargs)
.venv/lib/python3.10/site-packages/requests/adapters.py:565: in send
    raise ConnectionError(e, request=request)
E   requests.exceptions.ConnectionError: HTTPConnectionPool(host='localhost', port=3000): Max retries exceeded with url: /rpc (Caused by NewConnectionError('&lt;urllib3.connection.HTTPConnection object at 0x7f13f9205570&gt;: Failed to establish a new connection: [Errno 111] Connection refused'))</failure><system-out>--------------------------------- Captured Log ---------------------------------

--------------------------------- Captured Out ---------------------------------

</system-out><system-err>--------------------------------- Captured Err ---------------------------------

</system-err></testcase></testsuite></testsuites>